2025-06-01 00:05:42,059 - app.api.routes - ERROR - Error getting clubs: (psycopg2.OperationalError) could not receive data from server: No route to host
SSL SYSCALL error: No route to host

[SQL: SELECT clubs.id AS clubs_id, clubs.name AS clubs_name, clubs.location AS clubs_location, clubs.address AS clubs_address, clubs.description AS clubs_description, clubs.established_year AS clubs_established_year, clubs.meeting_times AS clubs_meeting_times, clubs.contact_email AS clubs_contact_email, clubs.contact_phone AS clubs_contact_phone, clubs.website_url AS clubs_website_url, clubs.social_media AS clubs_social_media, clubs.membership_fee AS clubs_membership_fee, clubs.skill_level AS clubs_skill_level, clubs.typical_routes AS clubs_typical_routes, clubs.group_size AS clubs_group_size, clubs.logo_url AS clubs_logo_url, clubs.photos AS clubs_photos, clubs.amenities AS clubs_amenities 
FROM clubs]
(Background on this error at: https://sqlalche.me/e/20/e3q8)
Traceback (most recent call last):
  File "/Users/satyamtiwari/running-hub/running-hub/backend/venv/lib/python3.9/site-packages/sqlalchemy/engine/base.py", line 1969, in _exec_single_context
    self.dialect.do_execute(
  File "/Users/satyamtiwari/running-hub/running-hub/backend/venv/lib/python3.9/site-packages/sqlalchemy/engine/default.py", line 922, in do_execute
    cursor.execute(statement, parameters)
psycopg2.OperationalError: could not receive data from server: No route to host
SSL SYSCALL error: No route to host


The above exception was the direct cause of the following exception:

Traceback (most recent call last):
  File "/Users/satyamtiwari/running-hub/running-hub/backend/app/api/routes.py", line 97, in get_clubs
    clubs = db.query(ClubModel).all()
  File "/Users/satyamtiwari/running-hub/running-hub/backend/venv/lib/python3.9/site-packages/sqlalchemy/orm/query.py", line 2693, in all
    return self._iter().all()  # type: ignore
  File "/Users/satyamtiwari/running-hub/running-hub/backend/venv/lib/python3.9/site-packages/sqlalchemy/orm/query.py", line 2847, in _iter
    result: Union[ScalarResult[_T], Result[_T]] = self.session.execute(
  File "/Users/satyamtiwari/running-hub/running-hub/backend/venv/lib/python3.9/site-packages/sqlalchemy/orm/session.py", line 2308, in execute
    return self._execute_internal(
  File "/Users/satyamtiwari/running-hub/running-hub/backend/venv/lib/python3.9/site-packages/sqlalchemy/orm/session.py", line 2190, in _execute_internal
    result: Result[Any] = compile_state_cls.orm_execute_statement(
  File "/Users/satyamtiwari/running-hub/running-hub/backend/venv/lib/python3.9/site-packages/sqlalchemy/orm/context.py", line 293, in orm_execute_statement
    result = conn.execute(
  File "/Users/satyamtiwari/running-hub/running-hub/backend/venv/lib/python3.9/site-packages/sqlalchemy/engine/base.py", line 1416, in execute
    return meth(
  File "/Users/satyamtiwari/running-hub/running-hub/backend/venv/lib/python3.9/site-packages/sqlalchemy/sql/elements.py", line 516, in _execute_on_connection
    return connection._execute_clauseelement(
  File "/Users/satyamtiwari/running-hub/running-hub/backend/venv/lib/python3.9/site-packages/sqlalchemy/engine/base.py", line 1639, in _execute_clauseelement
    ret = self._execute_context(
  File "/Users/satyamtiwari/running-hub/running-hub/backend/venv/lib/python3.9/site-packages/sqlalchemy/engine/base.py", line 1848, in _execute_context
    return self._exec_single_context(
  File "/Users/satyamtiwari/running-hub/running-hub/backend/venv/lib/python3.9/site-packages/sqlalchemy/engine/base.py", line 1988, in _exec_single_context
    self._handle_dbapi_exception(
  File "/Users/satyamtiwari/running-hub/running-hub/backend/venv/lib/python3.9/site-packages/sqlalchemy/engine/base.py", line 2343, in _handle_dbapi_exception
    raise sqlalchemy_exception.with_traceback(exc_info[2]) from e
  File "/Users/satyamtiwari/running-hub/running-hub/backend/venv/lib/python3.9/site-packages/sqlalchemy/engine/base.py", line 1969, in _exec_single_context
    self.dialect.do_execute(
  File "/Users/satyamtiwari/running-hub/running-hub/backend/venv/lib/python3.9/site-packages/sqlalchemy/engine/default.py", line 922, in do_execute
    cursor.execute(statement, parameters)
sqlalchemy.exc.OperationalError: (psycopg2.OperationalError) could not receive data from server: No route to host
SSL SYSCALL error: No route to host

[SQL: SELECT clubs.id AS clubs_id, clubs.name AS clubs_name, clubs.location AS clubs_location, clubs.address AS clubs_address, clubs.description AS clubs_description, clubs.established_year AS clubs_established_year, clubs.meeting_times AS clubs_meeting_times, clubs.contact_email AS clubs_contact_email, clubs.contact_phone AS clubs_contact_phone, clubs.website_url AS clubs_website_url, clubs.social_media AS clubs_social_media, clubs.membership_fee AS clubs_membership_fee, clubs.skill_level AS clubs_skill_level, clubs.typical_routes AS clubs_typical_routes, clubs.group_size AS clubs_group_size, clubs.logo_url AS clubs_logo_url, clubs.photos AS clubs_photos, clubs.amenities AS clubs_amenities 
FROM clubs]
(Background on this error at: https://sqlalche.me/e/20/e3q8)
2025-06-01 00:05:42,065 - app.api.routes - INFO - GET /events request from 127.0.0.1
2025-06-01 00:05:42,070 - app.api.routes - ERROR - Error getting events: (psycopg2.OperationalError) could not translate host name "ep-small-unit-a1h4gsi7-pooler.ap-southeast-1.aws.neon.tech" to address: nodename nor servname provided, or not known

(Background on this error at: https://sqlalche.me/e/20/e3q8)
Traceback (most recent call last):
  File "/Users/satyamtiwari/running-hub/running-hub/backend/venv/lib/python3.9/site-packages/sqlalchemy/engine/base.py", line 145, in __init__
    self._dbapi_connection = engine.raw_connection()
  File "/Users/satyamtiwari/running-hub/running-hub/backend/venv/lib/python3.9/site-packages/sqlalchemy/engine/base.py", line 3292, in raw_connection
    return self.pool.connect()
  File "/Users/satyamtiwari/running-hub/running-hub/backend/venv/lib/python3.9/site-packages/sqlalchemy/pool/base.py", line 452, in connect
    return _ConnectionFairy._checkout(self)
  File "/Users/satyamtiwari/running-hub/running-hub/backend/venv/lib/python3.9/site-packages/sqlalchemy/pool/base.py", line 1269, in _checkout
    fairy = _ConnectionRecord.checkout(pool)
  File "/Users/satyamtiwari/running-hub/running-hub/backend/venv/lib/python3.9/site-packages/sqlalchemy/pool/base.py", line 722, in checkout
    rec._checkin_failed(err, _fairy_was_created=False)
  File "/Users/satyamtiwari/running-hub/running-hub/backend/venv/lib/python3.9/site-packages/sqlalchemy/util/langhelpers.py", line 146, in __exit__
    raise exc_value.with_traceback(exc_tb)
  File "/Users/satyamtiwari/running-hub/running-hub/backend/venv/lib/python3.9/site-packages/sqlalchemy/pool/base.py", line 719, in checkout
    dbapi_connection = rec.get_connection()
  File "/Users/satyamtiwari/running-hub/running-hub/backend/venv/lib/python3.9/site-packages/sqlalchemy/pool/base.py", line 868, in get_connection
    self.__connect()
  File "/Users/satyamtiwari/running-hub/running-hub/backend/venv/lib/python3.9/site-packages/sqlalchemy/pool/base.py", line 903, in __connect
    pool.logger.debug("Error on connect(): %s", e)
  File "/Users/satyamtiwari/running-hub/running-hub/backend/venv/lib/python3.9/site-packages/sqlalchemy/util/langhelpers.py", line 146, in __exit__
    raise exc_value.with_traceback(exc_tb)
  File "/Users/satyamtiwari/running-hub/running-hub/backend/venv/lib/python3.9/site-packages/sqlalchemy/pool/base.py", line 898, in __connect
    self.dbapi_connection = connection = pool._invoke_creator(self)
  File "/Users/satyamtiwari/running-hub/running-hub/backend/venv/lib/python3.9/site-packages/sqlalchemy/engine/create.py", line 637, in connect
    return dialect.connect(*cargs, **cparams)
  File "/Users/satyamtiwari/running-hub/running-hub/backend/venv/lib/python3.9/site-packages/sqlalchemy/engine/default.py", line 616, in connect
    return self.loaded_dbapi.connect(*cargs, **cparams)
  File "/Users/satyamtiwari/running-hub/running-hub/backend/venv/lib/python3.9/site-packages/psycopg2/__init__.py", line 122, in connect
    conn = _connect(dsn, connection_factory=connection_factory, **kwasync)
psycopg2.OperationalError: could not translate host name "ep-small-unit-a1h4gsi7-pooler.ap-southeast-1.aws.neon.tech" to address: nodename nor servname provided, or not known


The above exception was the direct cause of the following exception:

Traceback (most recent call last):
  File "/Users/satyamtiwari/running-hub/running-hub/backend/app/api/routes.py", line 37, in get_events
    events = db.query(EventModel).all()
  File "/Users/satyamtiwari/running-hub/running-hub/backend/venv/lib/python3.9/site-packages/sqlalchemy/orm/query.py", line 2693, in all
    return self._iter().all()  # type: ignore
  File "/Users/satyamtiwari/running-hub/running-hub/backend/venv/lib/python3.9/site-packages/sqlalchemy/orm/query.py", line 2847, in _iter
    result: Union[ScalarResult[_T], Result[_T]] = self.session.execute(
  File "/Users/satyamtiwari/running-hub/running-hub/backend/venv/lib/python3.9/site-packages/sqlalchemy/orm/session.py", line 2308, in execute
    return self._execute_internal(
  File "/Users/satyamtiwari/running-hub/running-hub/backend/venv/lib/python3.9/site-packages/sqlalchemy/orm/session.py", line 2180, in _execute_internal
    conn = self._connection_for_bind(bind)
  File "/Users/satyamtiwari/running-hub/running-hub/backend/venv/lib/python3.9/site-packages/sqlalchemy/orm/session.py", line 2047, in _connection_for_bind
    return trans._connection_for_bind(engine, execution_options)
  File "<string>", line 2, in _connection_for_bind
  File "/Users/satyamtiwari/running-hub/running-hub/backend/venv/lib/python3.9/site-packages/sqlalchemy/orm/state_changes.py", line 139, in _go
    ret_value = fn(self, *arg, **kw)
  File "/Users/satyamtiwari/running-hub/running-hub/backend/venv/lib/python3.9/site-packages/sqlalchemy/orm/session.py", line 1143, in _connection_for_bind
    conn = bind.connect()
  File "/Users/satyamtiwari/running-hub/running-hub/backend/venv/lib/python3.9/site-packages/sqlalchemy/engine/base.py", line 3268, in connect
    return self._connection_cls(self)
  File "/Users/satyamtiwari/running-hub/running-hub/backend/venv/lib/python3.9/site-packages/sqlalchemy/engine/base.py", line 147, in __init__
    Connection._handle_dbapi_exception_noconnection(
  File "/Users/satyamtiwari/running-hub/running-hub/backend/venv/lib/python3.9/site-packages/sqlalchemy/engine/base.py", line 2430, in _handle_dbapi_exception_noconnection
    raise sqlalchemy_exception.with_traceback(exc_info[2]) from e
  File "/Users/satyamtiwari/running-hub/running-hub/backend/venv/lib/python3.9/site-packages/sqlalchemy/engine/base.py", line 145, in __init__
    self._dbapi_connection = engine.raw_connection()
  File "/Users/satyamtiwari/running-hub/running-hub/backend/venv/lib/python3.9/site-packages/sqlalchemy/engine/base.py", line 3292, in raw_connection
    return self.pool.connect()
  File "/Users/satyamtiwari/running-hub/running-hub/backend/venv/lib/python3.9/site-packages/sqlalchemy/pool/base.py", line 452, in connect
    return _ConnectionFairy._checkout(self)
  File "/Users/satyamtiwari/running-hub/running-hub/backend/venv/lib/python3.9/site-packages/sqlalchemy/pool/base.py", line 1269, in _checkout
    fairy = _ConnectionRecord.checkout(pool)
  File "/Users/satyamtiwari/running-hub/running-hub/backend/venv/lib/python3.9/site-packages/sqlalchemy/pool/base.py", line 722, in checkout
    rec._checkin_failed(err, _fairy_was_created=False)
  File "/Users/satyamtiwari/running-hub/running-hub/backend/venv/lib/python3.9/site-packages/sqlalchemy/util/langhelpers.py", line 146, in __exit__
    raise exc_value.with_traceback(exc_tb)
  File "/Users/satyamtiwari/running-hub/running-hub/backend/venv/lib/python3.9/site-packages/sqlalchemy/pool/base.py", line 719, in checkout
    dbapi_connection = rec.get_connection()
  File "/Users/satyamtiwari/running-hub/running-hub/backend/venv/lib/python3.9/site-packages/sqlalchemy/pool/base.py", line 868, in get_connection
    self.__connect()
  File "/Users/satyamtiwari/running-hub/running-hub/backend/venv/lib/python3.9/site-packages/sqlalchemy/pool/base.py", line 903, in __connect
    pool.logger.debug("Error on connect(): %s", e)
  File "/Users/satyamtiwari/running-hub/running-hub/backend/venv/lib/python3.9/site-packages/sqlalchemy/util/langhelpers.py", line 146, in __exit__
    raise exc_value.with_traceback(exc_tb)
  File "/Users/satyamtiwari/running-hub/running-hub/backend/venv/lib/python3.9/site-packages/sqlalchemy/pool/base.py", line 898, in __connect
    self.dbapi_connection = connection = pool._invoke_creator(self)
  File "/Users/satyamtiwari/running-hub/running-hub/backend/venv/lib/python3.9/site-packages/sqlalchemy/engine/create.py", line 637, in connect
    return dialect.connect(*cargs, **cparams)
  File "/Users/satyamtiwari/running-hub/running-hub/backend/venv/lib/python3.9/site-packages/sqlalchemy/engine/default.py", line 616, in connect
    return self.loaded_dbapi.connect(*cargs, **cparams)
  File "/Users/satyamtiwari/running-hub/running-hub/backend/venv/lib/python3.9/site-packages/psycopg2/__init__.py", line 122, in connect
    conn = _connect(dsn, connection_factory=connection_factory, **kwasync)
sqlalchemy.exc.OperationalError: (psycopg2.OperationalError) could not translate host name "ep-small-unit-a1h4gsi7-pooler.ap-southeast-1.aws.neon.tech" to address: nodename nor servname provided, or not known

(Background on this error at: https://sqlalche.me/e/20/e3q8)
2025-06-01 09:39:33,919 - app.api.routes - INFO - GET /events request from 127.0.0.1
2025-06-01 09:39:35,076 - app.api.routes - INFO - Retrieved 6 events from database.
2025-06-01 09:39:35,084 - app.api.routes - INFO - GET /clubs request from 127.0.0.1
2025-06-01 09:39:35,807 - app.api.routes - INFO - Retrieved 1 clubs from database.
2025-06-01 09:53:50,005 - app.api.routes - INFO - GET /events request from 127.0.0.1
2025-06-01 09:53:51,125 - app.api.routes - INFO - Retrieved 6 events from database.
2025-06-01 09:53:51,133 - app.api.routes - INFO - GET /clubs request from 127.0.0.1
2025-06-01 09:53:51,134 - app.api.routes - ERROR - Error getting clubs: (psycopg2.OperationalError) SSL SYSCALL error: EOF detected

[SQL: SELECT clubs.id AS clubs_id, clubs.name AS clubs_name, clubs.location AS clubs_location, clubs.address AS clubs_address, clubs.description AS clubs_description, clubs.established_year AS clubs_established_year, clubs.meeting_times AS clubs_meeting_times, clubs.contact_email AS clubs_contact_email, clubs.contact_phone AS clubs_contact_phone, clubs.website_url AS clubs_website_url, clubs.social_media AS clubs_social_media, clubs.membership_fee AS clubs_membership_fee, clubs.skill_level AS clubs_skill_level, clubs.typical_routes AS clubs_typical_routes, clubs.group_size AS clubs_group_size, clubs.logo_url AS clubs_logo_url, clubs.photos AS clubs_photos, clubs.amenities AS clubs_amenities 
FROM clubs]
(Background on this error at: https://sqlalche.me/e/20/e3q8)
Traceback (most recent call last):
  File "/Users/satyamtiwari/running-hub/running-hub/backend/venv/lib/python3.9/site-packages/sqlalchemy/engine/base.py", line 1969, in _exec_single_context
    self.dialect.do_execute(
  File "/Users/satyamtiwari/running-hub/running-hub/backend/venv/lib/python3.9/site-packages/sqlalchemy/engine/default.py", line 922, in do_execute
    cursor.execute(statement, parameters)
psycopg2.OperationalError: SSL SYSCALL error: EOF detected


The above exception was the direct cause of the following exception:

Traceback (most recent call last):
  File "/Users/satyamtiwari/running-hub/running-hub/backend/app/api/routes.py", line 97, in get_clubs
    clubs = db.query(ClubModel).all()
  File "/Users/satyamtiwari/running-hub/running-hub/backend/venv/lib/python3.9/site-packages/sqlalchemy/orm/query.py", line 2693, in all
    return self._iter().all()  # type: ignore
  File "/Users/satyamtiwari/running-hub/running-hub/backend/venv/lib/python3.9/site-packages/sqlalchemy/orm/query.py", line 2847, in _iter
    result: Union[ScalarResult[_T], Result[_T]] = self.session.execute(
  File "/Users/satyamtiwari/running-hub/running-hub/backend/venv/lib/python3.9/site-packages/sqlalchemy/orm/session.py", line 2308, in execute
    return self._execute_internal(
  File "/Users/satyamtiwari/running-hub/running-hub/backend/venv/lib/python3.9/site-packages/sqlalchemy/orm/session.py", line 2190, in _execute_internal
    result: Result[Any] = compile_state_cls.orm_execute_statement(
  File "/Users/satyamtiwari/running-hub/running-hub/backend/venv/lib/python3.9/site-packages/sqlalchemy/orm/context.py", line 293, in orm_execute_statement
    result = conn.execute(
  File "/Users/satyamtiwari/running-hub/running-hub/backend/venv/lib/python3.9/site-packages/sqlalchemy/engine/base.py", line 1416, in execute
    return meth(
  File "/Users/satyamtiwari/running-hub/running-hub/backend/venv/lib/python3.9/site-packages/sqlalchemy/sql/elements.py", line 516, in _execute_on_connection
    return connection._execute_clauseelement(
  File "/Users/satyamtiwari/running-hub/running-hub/backend/venv/lib/python3.9/site-packages/sqlalchemy/engine/base.py", line 1639, in _execute_clauseelement
    ret = self._execute_context(
  File "/Users/satyamtiwari/running-hub/running-hub/backend/venv/lib/python3.9/site-packages/sqlalchemy/engine/base.py", line 1848, in _execute_context
    return self._exec_single_context(
  File "/Users/satyamtiwari/running-hub/running-hub/backend/venv/lib/python3.9/site-packages/sqlalchemy/engine/base.py", line 1988, in _exec_single_context
    self._handle_dbapi_exception(
  File "/Users/satyamtiwari/running-hub/running-hub/backend/venv/lib/python3.9/site-packages/sqlalchemy/engine/base.py", line 2343, in _handle_dbapi_exception
    raise sqlalchemy_exception.with_traceback(exc_info[2]) from e
  File "/Users/satyamtiwari/running-hub/running-hub/backend/venv/lib/python3.9/site-packages/sqlalchemy/engine/base.py", line 1969, in _exec_single_context
    self.dialect.do_execute(
  File "/Users/satyamtiwari/running-hub/running-hub/backend/venv/lib/python3.9/site-packages/sqlalchemy/engine/default.py", line 922, in do_execute
    cursor.execute(statement, parameters)
sqlalchemy.exc.OperationalError: (psycopg2.OperationalError) SSL SYSCALL error: EOF detected

[SQL: SELECT clubs.id AS clubs_id, clubs.name AS clubs_name, clubs.location AS clubs_location, clubs.address AS clubs_address, clubs.description AS clubs_description, clubs.established_year AS clubs_established_year, clubs.meeting_times AS clubs_meeting_times, clubs.contact_email AS clubs_contact_email, clubs.contact_phone AS clubs_contact_phone, clubs.website_url AS clubs_website_url, clubs.social_media AS clubs_social_media, clubs.membership_fee AS clubs_membership_fee, clubs.skill_level AS clubs_skill_level, clubs.typical_routes AS clubs_typical_routes, clubs.group_size AS clubs_group_size, clubs.logo_url AS clubs_logo_url, clubs.photos AS clubs_photos, clubs.amenities AS clubs_amenities 
FROM clubs]
(Background on this error at: https://sqlalche.me/e/20/e3q8)
2025-06-01 09:54:54,976 - app.api.routes - INFO - GET /events request from 127.0.0.1
2025-06-01 09:54:55,577 - app.api.routes - INFO - Retrieved 6 events from database.
2025-06-01 10:02:11,970 - app.api.routes - INFO - GET /events request from 127.0.0.1
2025-06-01 10:02:12,927 - app.api.routes - INFO - Retrieved 6 events from database.
2025-06-01 10:02:15,864 - app.api.routes - INFO - GET /events request from 127.0.0.1
2025-06-01 10:02:16,445 - app.api.routes - INFO - Retrieved 6 events from database.
2025-06-01 10:02:16,447 - app.api.routes - INFO - GET /clubs request from 127.0.0.1
2025-06-01 10:02:16,448 - app.api.routes - ERROR - Error getting clubs: (psycopg2.OperationalError) SSL SYSCALL error: EOF detected

[SQL: SELECT clubs.id AS clubs_id, clubs.name AS clubs_name, clubs.location AS clubs_location, clubs.address AS clubs_address, clubs.description AS clubs_description, clubs.established_year AS clubs_established_year, clubs.meeting_times AS clubs_meeting_times, clubs.contact_email AS clubs_contact_email, clubs.contact_phone AS clubs_contact_phone, clubs.website_url AS clubs_website_url, clubs.social_media AS clubs_social_media, clubs.membership_fee AS clubs_membership_fee, clubs.skill_level AS clubs_skill_level, clubs.typical_routes AS clubs_typical_routes, clubs.group_size AS clubs_group_size, clubs.logo_url AS clubs_logo_url, clubs.photos AS clubs_photos, clubs.amenities AS clubs_amenities 
FROM clubs]
(Background on this error at: https://sqlalche.me/e/20/e3q8)
Traceback (most recent call last):
  File "/Users/satyamtiwari/running-hub/running-hub/backend/venv/lib/python3.9/site-packages/sqlalchemy/engine/base.py", line 1969, in _exec_single_context
    self.dialect.do_execute(
  File "/Users/satyamtiwari/running-hub/running-hub/backend/venv/lib/python3.9/site-packages/sqlalchemy/engine/default.py", line 922, in do_execute
    cursor.execute(statement, parameters)
psycopg2.OperationalError: SSL SYSCALL error: EOF detected


The above exception was the direct cause of the following exception:

Traceback (most recent call last):
  File "/Users/satyamtiwari/running-hub/running-hub/backend/app/api/routes.py", line 97, in get_clubs
    clubs = db.query(ClubModel).all()
  File "/Users/satyamtiwari/running-hub/running-hub/backend/venv/lib/python3.9/site-packages/sqlalchemy/orm/query.py", line 2693, in all
    return self._iter().all()  # type: ignore
  File "/Users/satyamtiwari/running-hub/running-hub/backend/venv/lib/python3.9/site-packages/sqlalchemy/orm/query.py", line 2847, in _iter
    result: Union[ScalarResult[_T], Result[_T]] = self.session.execute(
  File "/Users/satyamtiwari/running-hub/running-hub/backend/venv/lib/python3.9/site-packages/sqlalchemy/orm/session.py", line 2308, in execute
    return self._execute_internal(
  File "/Users/satyamtiwari/running-hub/running-hub/backend/venv/lib/python3.9/site-packages/sqlalchemy/orm/session.py", line 2190, in _execute_internal
    result: Result[Any] = compile_state_cls.orm_execute_statement(
  File "/Users/satyamtiwari/running-hub/running-hub/backend/venv/lib/python3.9/site-packages/sqlalchemy/orm/context.py", line 293, in orm_execute_statement
    result = conn.execute(
  File "/Users/satyamtiwari/running-hub/running-hub/backend/venv/lib/python3.9/site-packages/sqlalchemy/engine/base.py", line 1416, in execute
    return meth(
  File "/Users/satyamtiwari/running-hub/running-hub/backend/venv/lib/python3.9/site-packages/sqlalchemy/sql/elements.py", line 516, in _execute_on_connection
    return connection._execute_clauseelement(
  File "/Users/satyamtiwari/running-hub/running-hub/backend/venv/lib/python3.9/site-packages/sqlalchemy/engine/base.py", line 1639, in _execute_clauseelement
    ret = self._execute_context(
  File "/Users/satyamtiwari/running-hub/running-hub/backend/venv/lib/python3.9/site-packages/sqlalchemy/engine/base.py", line 1848, in _execute_context
    return self._exec_single_context(
  File "/Users/satyamtiwari/running-hub/running-hub/backend/venv/lib/python3.9/site-packages/sqlalchemy/engine/base.py", line 1988, in _exec_single_context
    self._handle_dbapi_exception(
  File "/Users/satyamtiwari/running-hub/running-hub/backend/venv/lib/python3.9/site-packages/sqlalchemy/engine/base.py", line 2343, in _handle_dbapi_exception
    raise sqlalchemy_exception.with_traceback(exc_info[2]) from e
  File "/Users/satyamtiwari/running-hub/running-hub/backend/venv/lib/python3.9/site-packages/sqlalchemy/engine/base.py", line 1969, in _exec_single_context
    self.dialect.do_execute(
  File "/Users/satyamtiwari/running-hub/running-hub/backend/venv/lib/python3.9/site-packages/sqlalchemy/engine/default.py", line 922, in do_execute
    cursor.execute(statement, parameters)
sqlalchemy.exc.OperationalError: (psycopg2.OperationalError) SSL SYSCALL error: EOF detected

[SQL: SELECT clubs.id AS clubs_id, clubs.name AS clubs_name, clubs.location AS clubs_location, clubs.address AS clubs_address, clubs.description AS clubs_description, clubs.established_year AS clubs_established_year, clubs.meeting_times AS clubs_meeting_times, clubs.contact_email AS clubs_contact_email, clubs.contact_phone AS clubs_contact_phone, clubs.website_url AS clubs_website_url, clubs.social_media AS clubs_social_media, clubs.membership_fee AS clubs_membership_fee, clubs.skill_level AS clubs_skill_level, clubs.typical_routes AS clubs_typical_routes, clubs.group_size AS clubs_group_size, clubs.logo_url AS clubs_logo_url, clubs.photos AS clubs_photos, clubs.amenities AS clubs_amenities 
FROM clubs]
(Background on this error at: https://sqlalche.me/e/20/e3q8)
2025-06-01 10:02:18,460 - app.api.routes - INFO - GET /clubs request from 127.0.0.1
2025-06-01 10:02:19,056 - app.api.routes - INFO - Retrieved 1 clubs from database.
2025-06-01 10:02:41,052 - app.api.routes - INFO - GET /events request from 127.0.0.1
2025-06-01 10:02:41,785 - app.api.routes - INFO - Retrieved 6 events from database.
2025-06-01 10:02:41,786 - app.api.routes - INFO - GET /clubs request from 127.0.0.1
2025-06-01 10:02:42,410 - app.api.routes - INFO - Retrieved 1 clubs from database.
2025-06-01 10:04:54,253 - app.api.routes - INFO - GET /events request from 127.0.0.1
2025-06-01 10:04:54,426 - app.api.routes - INFO - Retrieved 6 events from database.
2025-06-01 10:04:54,427 - app.api.routes - INFO - GET /clubs request from 127.0.0.1
2025-06-01 10:04:54,572 - app.api.routes - INFO - Retrieved 1 clubs from database.
2025-06-01 10:11:50,334 - app.api.routes - INFO - GET /events request from 127.0.0.1
2025-06-01 10:11:50,809 - app.api.routes - ERROR - Error getting events: (psycopg2.OperationalError) server closed the connection unexpectedly
	This probably means the server terminated abnormally
	before or while processing the request.
server closed the connection unexpectedly
	This probably means the server terminated abnormally
	before or while processing the request.

[SQL: SELECT events.id AS events_id, events.title AS events_title, events.date AS events_date, events.location AS events_location, events.address AS events_address, events.categories AS events_categories, events.price AS events_price, events.url AS events_url, events.source AS events_source, events.description AS events_description, events.registration_closes AS events_registration_closes, events.scraped_at AS events_scraped_at, events.image_url AS events_image_url, events.created_at AS events_created_at, events.updated_at AS events_updated_at, events.is_verified AS events_is_verified 
FROM events]
(Background on this error at: https://sqlalche.me/e/20/e3q8)
Traceback (most recent call last):
  File "/Users/satyamtiwari/running-hub/running-hub/backend/venv/lib/python3.9/site-packages/sqlalchemy/engine/base.py", line 1969, in _exec_single_context
    self.dialect.do_execute(
  File "/Users/satyamtiwari/running-hub/running-hub/backend/venv/lib/python3.9/site-packages/sqlalchemy/engine/default.py", line 922, in do_execute
    cursor.execute(statement, parameters)
psycopg2.OperationalError: server closed the connection unexpectedly
	This probably means the server terminated abnormally
	before or while processing the request.
server closed the connection unexpectedly
	This probably means the server terminated abnormally
	before or while processing the request.


The above exception was the direct cause of the following exception:

Traceback (most recent call last):
  File "/Users/satyamtiwari/running-hub/running-hub/backend/app/api/routes.py", line 37, in get_events
    events = db.query(EventModel).all()
  File "/Users/satyamtiwari/running-hub/running-hub/backend/venv/lib/python3.9/site-packages/sqlalchemy/orm/query.py", line 2693, in all
    return self._iter().all()  # type: ignore
  File "/Users/satyamtiwari/running-hub/running-hub/backend/venv/lib/python3.9/site-packages/sqlalchemy/orm/query.py", line 2847, in _iter
    result: Union[ScalarResult[_T], Result[_T]] = self.session.execute(
  File "/Users/satyamtiwari/running-hub/running-hub/backend/venv/lib/python3.9/site-packages/sqlalchemy/orm/session.py", line 2308, in execute
    return self._execute_internal(
  File "/Users/satyamtiwari/running-hub/running-hub/backend/venv/lib/python3.9/site-packages/sqlalchemy/orm/session.py", line 2190, in _execute_internal
    result: Result[Any] = compile_state_cls.orm_execute_statement(
  File "/Users/satyamtiwari/running-hub/running-hub/backend/venv/lib/python3.9/site-packages/sqlalchemy/orm/context.py", line 293, in orm_execute_statement
    result = conn.execute(
  File "/Users/satyamtiwari/running-hub/running-hub/backend/venv/lib/python3.9/site-packages/sqlalchemy/engine/base.py", line 1416, in execute
    return meth(
  File "/Users/satyamtiwari/running-hub/running-hub/backend/venv/lib/python3.9/site-packages/sqlalchemy/sql/elements.py", line 516, in _execute_on_connection
    return connection._execute_clauseelement(
  File "/Users/satyamtiwari/running-hub/running-hub/backend/venv/lib/python3.9/site-packages/sqlalchemy/engine/base.py", line 1639, in _execute_clauseelement
    ret = self._execute_context(
  File "/Users/satyamtiwari/running-hub/running-hub/backend/venv/lib/python3.9/site-packages/sqlalchemy/engine/base.py", line 1848, in _execute_context
    return self._exec_single_context(
  File "/Users/satyamtiwari/running-hub/running-hub/backend/venv/lib/python3.9/site-packages/sqlalchemy/engine/base.py", line 1988, in _exec_single_context
    self._handle_dbapi_exception(
  File "/Users/satyamtiwari/running-hub/running-hub/backend/venv/lib/python3.9/site-packages/sqlalchemy/engine/base.py", line 2343, in _handle_dbapi_exception
    raise sqlalchemy_exception.with_traceback(exc_info[2]) from e
  File "/Users/satyamtiwari/running-hub/running-hub/backend/venv/lib/python3.9/site-packages/sqlalchemy/engine/base.py", line 1969, in _exec_single_context
    self.dialect.do_execute(
  File "/Users/satyamtiwari/running-hub/running-hub/backend/venv/lib/python3.9/site-packages/sqlalchemy/engine/default.py", line 922, in do_execute
    cursor.execute(statement, parameters)
sqlalchemy.exc.OperationalError: (psycopg2.OperationalError) server closed the connection unexpectedly
	This probably means the server terminated abnormally
	before or while processing the request.
server closed the connection unexpectedly
	This probably means the server terminated abnormally
	before or while processing the request.

[SQL: SELECT events.id AS events_id, events.title AS events_title, events.date AS events_date, events.location AS events_location, events.address AS events_address, events.categories AS events_categories, events.price AS events_price, events.url AS events_url, events.source AS events_source, events.description AS events_description, events.registration_closes AS events_registration_closes, events.scraped_at AS events_scraped_at, events.image_url AS events_image_url, events.created_at AS events_created_at, events.updated_at AS events_updated_at, events.is_verified AS events_is_verified 
FROM events]
(Background on this error at: https://sqlalche.me/e/20/e3q8)
2025-06-01 10:11:50,813 - app.api.routes - INFO - GET /clubs request from 127.0.0.1
2025-06-01 10:11:51,875 - app.api.routes - INFO - Retrieved 1 clubs from database.
2025-06-01 10:11:52,195 - app.api.routes - INFO - GET /clubs request from 127.0.0.1
2025-06-01 10:11:52,821 - app.api.routes - INFO - Retrieved 1 clubs from database.
2025-06-01 10:11:52,903 - app.api.routes - INFO - GET /events request from 127.0.0.1
2025-06-01 10:11:53,521 - app.api.routes - INFO - Retrieved 6 events from database.
2025-06-01 10:16:50,118 - app.api.routes - INFO - GET /events request from 127.0.0.1
2025-06-01 10:16:50,308 - app.api.routes - INFO - Retrieved 6 events from database.
2025-06-01 10:16:50,331 - app.api.routes - INFO - GET /clubs request from 127.0.0.1
2025-06-01 10:16:50,477 - app.api.routes - INFO - Retrieved 1 clubs from database.
2025-06-01 11:02:19,135 - app.api.routes - INFO - GET /events request from 127.0.0.1
2025-06-01 11:02:19,151 - app.api.routes - ERROR - Error getting events: (psycopg2.OperationalError) SSL SYSCALL error: EOF detected

[SQL: SELECT events.id AS events_id, events.title AS events_title, events.date AS events_date, events.location AS events_location, events.address AS events_address, events.categories AS events_categories, events.price AS events_price, events.url AS events_url, events.source AS events_source, events.description AS events_description, events.registration_closes AS events_registration_closes, events.scraped_at AS events_scraped_at, events.image_url AS events_image_url, events.created_at AS events_created_at, events.updated_at AS events_updated_at, events.is_verified AS events_is_verified 
FROM events]
(Background on this error at: https://sqlalche.me/e/20/e3q8)
Traceback (most recent call last):
  File "/Users/satyamtiwari/running-hub/running-hub/backend/venv/lib/python3.9/site-packages/sqlalchemy/engine/base.py", line 1969, in _exec_single_context
    self.dialect.do_execute(
  File "/Users/satyamtiwari/running-hub/running-hub/backend/venv/lib/python3.9/site-packages/sqlalchemy/engine/default.py", line 922, in do_execute
    cursor.execute(statement, parameters)
psycopg2.OperationalError: SSL SYSCALL error: EOF detected


The above exception was the direct cause of the following exception:

Traceback (most recent call last):
  File "/Users/satyamtiwari/running-hub/running-hub/backend/app/api/routes.py", line 37, in get_events
    events = db.query(EventModel).all()
  File "/Users/satyamtiwari/running-hub/running-hub/backend/venv/lib/python3.9/site-packages/sqlalchemy/orm/query.py", line 2693, in all
    return self._iter().all()  # type: ignore
  File "/Users/satyamtiwari/running-hub/running-hub/backend/venv/lib/python3.9/site-packages/sqlalchemy/orm/query.py", line 2847, in _iter
    result: Union[ScalarResult[_T], Result[_T]] = self.session.execute(
  File "/Users/satyamtiwari/running-hub/running-hub/backend/venv/lib/python3.9/site-packages/sqlalchemy/orm/session.py", line 2308, in execute
    return self._execute_internal(
  File "/Users/satyamtiwari/running-hub/running-hub/backend/venv/lib/python3.9/site-packages/sqlalchemy/orm/session.py", line 2190, in _execute_internal
    result: Result[Any] = compile_state_cls.orm_execute_statement(
  File "/Users/satyamtiwari/running-hub/running-hub/backend/venv/lib/python3.9/site-packages/sqlalchemy/orm/context.py", line 293, in orm_execute_statement
    result = conn.execute(
  File "/Users/satyamtiwari/running-hub/running-hub/backend/venv/lib/python3.9/site-packages/sqlalchemy/engine/base.py", line 1416, in execute
    return meth(
  File "/Users/satyamtiwari/running-hub/running-hub/backend/venv/lib/python3.9/site-packages/sqlalchemy/sql/elements.py", line 516, in _execute_on_connection
    return connection._execute_clauseelement(
  File "/Users/satyamtiwari/running-hub/running-hub/backend/venv/lib/python3.9/site-packages/sqlalchemy/engine/base.py", line 1639, in _execute_clauseelement
    ret = self._execute_context(
  File "/Users/satyamtiwari/running-hub/running-hub/backend/venv/lib/python3.9/site-packages/sqlalchemy/engine/base.py", line 1848, in _execute_context
    return self._exec_single_context(
  File "/Users/satyamtiwari/running-hub/running-hub/backend/venv/lib/python3.9/site-packages/sqlalchemy/engine/base.py", line 1988, in _exec_single_context
    self._handle_dbapi_exception(
  File "/Users/satyamtiwari/running-hub/running-hub/backend/venv/lib/python3.9/site-packages/sqlalchemy/engine/base.py", line 2343, in _handle_dbapi_exception
    raise sqlalchemy_exception.with_traceback(exc_info[2]) from e
  File "/Users/satyamtiwari/running-hub/running-hub/backend/venv/lib/python3.9/site-packages/sqlalchemy/engine/base.py", line 1969, in _exec_single_context
    self.dialect.do_execute(
  File "/Users/satyamtiwari/running-hub/running-hub/backend/venv/lib/python3.9/site-packages/sqlalchemy/engine/default.py", line 922, in do_execute
    cursor.execute(statement, parameters)
sqlalchemy.exc.OperationalError: (psycopg2.OperationalError) SSL SYSCALL error: EOF detected

[SQL: SELECT events.id AS events_id, events.title AS events_title, events.date AS events_date, events.location AS events_location, events.address AS events_address, events.categories AS events_categories, events.price AS events_price, events.url AS events_url, events.source AS events_source, events.description AS events_description, events.registration_closes AS events_registration_closes, events.scraped_at AS events_scraped_at, events.image_url AS events_image_url, events.created_at AS events_created_at, events.updated_at AS events_updated_at, events.is_verified AS events_is_verified 
FROM events]
(Background on this error at: https://sqlalche.me/e/20/e3q8)
2025-06-01 11:02:19,152 - app.api.routes - INFO - GET /clubs request from 127.0.0.1
2025-06-01 11:02:19,925 - app.api.routes - INFO - Retrieved 1 clubs from database.
2025-06-01 11:02:25,127 - app.api.routes - INFO - GET /clubs request from 127.0.0.1
2025-06-01 11:02:25,732 - app.api.routes - INFO - Retrieved 1 clubs from database.
2025-06-01 11:19:09,130 - app.api.routes - INFO - GET /events request from 127.0.0.1
2025-06-01 11:19:10,176 - app.api.routes - INFO - Retrieved 6 events from database.
2025-06-01 11:19:10,182 - app.api.routes - INFO - GET /clubs request from 127.0.0.1
2025-06-01 11:19:10,182 - app.api.routes - ERROR - Error getting clubs: (psycopg2.OperationalError) SSL SYSCALL error: EOF detected

[SQL: SELECT clubs.id AS clubs_id, clubs.name AS clubs_name, clubs.location AS clubs_location, clubs.address AS clubs_address, clubs.description AS clubs_description, clubs.established_year AS clubs_established_year, clubs.meeting_times AS clubs_meeting_times, clubs.contact_email AS clubs_contact_email, clubs.contact_phone AS clubs_contact_phone, clubs.website_url AS clubs_website_url, clubs.social_media AS clubs_social_media, clubs.membership_fee AS clubs_membership_fee, clubs.skill_level AS clubs_skill_level, clubs.typical_routes AS clubs_typical_routes, clubs.group_size AS clubs_group_size, clubs.logo_url AS clubs_logo_url, clubs.photos AS clubs_photos, clubs.amenities AS clubs_amenities 
FROM clubs]
(Background on this error at: https://sqlalche.me/e/20/e3q8)
Traceback (most recent call last):
  File "/Users/satyamtiwari/running-hub/running-hub/backend/venv/lib/python3.9/site-packages/sqlalchemy/engine/base.py", line 1969, in _exec_single_context
    self.dialect.do_execute(
  File "/Users/satyamtiwari/running-hub/running-hub/backend/venv/lib/python3.9/site-packages/sqlalchemy/engine/default.py", line 922, in do_execute
    cursor.execute(statement, parameters)
psycopg2.OperationalError: SSL SYSCALL error: EOF detected


The above exception was the direct cause of the following exception:

Traceback (most recent call last):
  File "/Users/satyamtiwari/running-hub/running-hub/backend/app/api/routes.py", line 97, in get_clubs
    clubs = db.query(ClubModel).all()
  File "/Users/satyamtiwari/running-hub/running-hub/backend/venv/lib/python3.9/site-packages/sqlalchemy/orm/query.py", line 2693, in all
    return self._iter().all()  # type: ignore
  File "/Users/satyamtiwari/running-hub/running-hub/backend/venv/lib/python3.9/site-packages/sqlalchemy/orm/query.py", line 2847, in _iter
    result: Union[ScalarResult[_T], Result[_T]] = self.session.execute(
  File "/Users/satyamtiwari/running-hub/running-hub/backend/venv/lib/python3.9/site-packages/sqlalchemy/orm/session.py", line 2308, in execute
    return self._execute_internal(
  File "/Users/satyamtiwari/running-hub/running-hub/backend/venv/lib/python3.9/site-packages/sqlalchemy/orm/session.py", line 2190, in _execute_internal
    result: Result[Any] = compile_state_cls.orm_execute_statement(
  File "/Users/satyamtiwari/running-hub/running-hub/backend/venv/lib/python3.9/site-packages/sqlalchemy/orm/context.py", line 293, in orm_execute_statement
    result = conn.execute(
  File "/Users/satyamtiwari/running-hub/running-hub/backend/venv/lib/python3.9/site-packages/sqlalchemy/engine/base.py", line 1416, in execute
    return meth(
  File "/Users/satyamtiwari/running-hub/running-hub/backend/venv/lib/python3.9/site-packages/sqlalchemy/sql/elements.py", line 516, in _execute_on_connection
    return connection._execute_clauseelement(
  File "/Users/satyamtiwari/running-hub/running-hub/backend/venv/lib/python3.9/site-packages/sqlalchemy/engine/base.py", line 1639, in _execute_clauseelement
    ret = self._execute_context(
  File "/Users/satyamtiwari/running-hub/running-hub/backend/venv/lib/python3.9/site-packages/sqlalchemy/engine/base.py", line 1848, in _execute_context
    return self._exec_single_context(
  File "/Users/satyamtiwari/running-hub/running-hub/backend/venv/lib/python3.9/site-packages/sqlalchemy/engine/base.py", line 1988, in _exec_single_context
    self._handle_dbapi_exception(
  File "/Users/satyamtiwari/running-hub/running-hub/backend/venv/lib/python3.9/site-packages/sqlalchemy/engine/base.py", line 2343, in _handle_dbapi_exception
    raise sqlalchemy_exception.with_traceback(exc_info[2]) from e
  File "/Users/satyamtiwari/running-hub/running-hub/backend/venv/lib/python3.9/site-packages/sqlalchemy/engine/base.py", line 1969, in _exec_single_context
    self.dialect.do_execute(
  File "/Users/satyamtiwari/running-hub/running-hub/backend/venv/lib/python3.9/site-packages/sqlalchemy/engine/default.py", line 922, in do_execute
    cursor.execute(statement, parameters)
sqlalchemy.exc.OperationalError: (psycopg2.OperationalError) SSL SYSCALL error: EOF detected

[SQL: SELECT clubs.id AS clubs_id, clubs.name AS clubs_name, clubs.location AS clubs_location, clubs.address AS clubs_address, clubs.description AS clubs_description, clubs.established_year AS clubs_established_year, clubs.meeting_times AS clubs_meeting_times, clubs.contact_email AS clubs_contact_email, clubs.contact_phone AS clubs_contact_phone, clubs.website_url AS clubs_website_url, clubs.social_media AS clubs_social_media, clubs.membership_fee AS clubs_membership_fee, clubs.skill_level AS clubs_skill_level, clubs.typical_routes AS clubs_typical_routes, clubs.group_size AS clubs_group_size, clubs.logo_url AS clubs_logo_url, clubs.photos AS clubs_photos, clubs.amenities AS clubs_amenities 
FROM clubs]
(Background on this error at: https://sqlalche.me/e/20/e3q8)
2025-06-01 11:35:29,452 - app.api.routes - INFO - GET /events request from 127.0.0.1
2025-06-01 11:35:30,526 - app.api.routes - INFO - Retrieved 6 events from database.
2025-06-01 11:35:58,460 - app.api.routes - INFO - GET /events request from 127.0.0.1
2025-06-01 11:35:59,091 - app.api.routes - INFO - Retrieved 6 events from database.
2025-06-01 11:36:03,333 - app.api.routes - INFO - GET /events request from 127.0.0.1
2025-06-01 11:36:03,965 - app.api.routes - INFO - Retrieved 6 events from database.
2025-06-01 11:36:03,967 - app.api.routes - INFO - GET /clubs request from 127.0.0.1
2025-06-01 11:36:04,123 - app.api.routes - INFO - Retrieved 1 clubs from database.
2025-06-01 11:36:07,721 - app.api.routes - INFO - GET /events request from 127.0.0.1
2025-06-01 11:36:07,869 - app.api.routes - INFO - Retrieved 6 events from database.
2025-06-01 11:36:07,872 - app.api.routes - INFO - GET /clubs request from 127.0.0.1
2025-06-01 11:36:08,018 - app.api.routes - INFO - Retrieved 1 clubs from database.
2025-06-01 11:36:10,891 - app.api.routes - INFO - GET /events request from 127.0.0.1
2025-06-01 11:36:11,078 - app.api.routes - INFO - Retrieved 6 events from database.
2025-06-01 11:36:11,081 - app.api.routes - INFO - GET /clubs request from 127.0.0.1
2025-06-01 11:36:11,233 - app.api.routes - INFO - Retrieved 1 clubs from database.
2025-06-01 11:38:18,083 - app.api.routes - INFO - GET /events request from 127.0.0.1
2025-06-01 11:38:18,351 - app.api.routes - INFO - Retrieved 6 events from database.
2025-06-01 11:38:18,363 - app.api.routes - INFO - GET /clubs request from 127.0.0.1
2025-06-01 11:38:18,512 - app.api.routes - INFO - Retrieved 1 clubs from database.
2025-06-01 12:07:47,631 - app.api.routes - INFO - GET /events request from 127.0.0.1
2025-06-01 12:07:47,659 - app.api.routes - ERROR - Error getting events: (psycopg2.DatabaseError) could not receive data from server: Can't assign requested address
SSL SYSCALL error: Can't assign requested address

[SQL: SELECT events.id AS events_id, events.title AS events_title, events.date AS events_date, events.location AS events_location, events.address AS events_address, events.categories AS events_categories, events.price AS events_price, events.url AS events_url, events.source AS events_source, events.description AS events_description, events.registration_closes AS events_registration_closes, events.scraped_at AS events_scraped_at, events.image_url AS events_image_url, events.created_at AS events_created_at, events.updated_at AS events_updated_at, events.is_verified AS events_is_verified 
FROM events]
(Background on this error at: https://sqlalche.me/e/20/4xp6)
Traceback (most recent call last):
  File "/Users/satyamtiwari/running-hub/running-hub/backend/venv/lib/python3.9/site-packages/sqlalchemy/engine/base.py", line 1969, in _exec_single_context
    self.dialect.do_execute(
  File "/Users/satyamtiwari/running-hub/running-hub/backend/venv/lib/python3.9/site-packages/sqlalchemy/engine/default.py", line 922, in do_execute
    cursor.execute(statement, parameters)
psycopg2.DatabaseError: could not receive data from server: Can't assign requested address
SSL SYSCALL error: Can't assign requested address


The above exception was the direct cause of the following exception:

Traceback (most recent call last):
  File "/Users/satyamtiwari/running-hub/running-hub/backend/app/api/routes.py", line 37, in get_events
    events = db.query(EventModel).all()
  File "/Users/satyamtiwari/running-hub/running-hub/backend/venv/lib/python3.9/site-packages/sqlalchemy/orm/query.py", line 2693, in all
    return self._iter().all()  # type: ignore
  File "/Users/satyamtiwari/running-hub/running-hub/backend/venv/lib/python3.9/site-packages/sqlalchemy/orm/query.py", line 2847, in _iter
    result: Union[ScalarResult[_T], Result[_T]] = self.session.execute(
  File "/Users/satyamtiwari/running-hub/running-hub/backend/venv/lib/python3.9/site-packages/sqlalchemy/orm/session.py", line 2308, in execute
    return self._execute_internal(
  File "/Users/satyamtiwari/running-hub/running-hub/backend/venv/lib/python3.9/site-packages/sqlalchemy/orm/session.py", line 2190, in _execute_internal
    result: Result[Any] = compile_state_cls.orm_execute_statement(
  File "/Users/satyamtiwari/running-hub/running-hub/backend/venv/lib/python3.9/site-packages/sqlalchemy/orm/context.py", line 293, in orm_execute_statement
    result = conn.execute(
  File "/Users/satyamtiwari/running-hub/running-hub/backend/venv/lib/python3.9/site-packages/sqlalchemy/engine/base.py", line 1416, in execute
    return meth(
  File "/Users/satyamtiwari/running-hub/running-hub/backend/venv/lib/python3.9/site-packages/sqlalchemy/sql/elements.py", line 516, in _execute_on_connection
    return connection._execute_clauseelement(
  File "/Users/satyamtiwari/running-hub/running-hub/backend/venv/lib/python3.9/site-packages/sqlalchemy/engine/base.py", line 1639, in _execute_clauseelement
    ret = self._execute_context(
  File "/Users/satyamtiwari/running-hub/running-hub/backend/venv/lib/python3.9/site-packages/sqlalchemy/engine/base.py", line 1848, in _execute_context
    return self._exec_single_context(
  File "/Users/satyamtiwari/running-hub/running-hub/backend/venv/lib/python3.9/site-packages/sqlalchemy/engine/base.py", line 1988, in _exec_single_context
    self._handle_dbapi_exception(
  File "/Users/satyamtiwari/running-hub/running-hub/backend/venv/lib/python3.9/site-packages/sqlalchemy/engine/base.py", line 2343, in _handle_dbapi_exception
    raise sqlalchemy_exception.with_traceback(exc_info[2]) from e
  File "/Users/satyamtiwari/running-hub/running-hub/backend/venv/lib/python3.9/site-packages/sqlalchemy/engine/base.py", line 1969, in _exec_single_context
    self.dialect.do_execute(
  File "/Users/satyamtiwari/running-hub/running-hub/backend/venv/lib/python3.9/site-packages/sqlalchemy/engine/default.py", line 922, in do_execute
    cursor.execute(statement, parameters)
sqlalchemy.exc.DatabaseError: (psycopg2.DatabaseError) could not receive data from server: Can't assign requested address
SSL SYSCALL error: Can't assign requested address

[SQL: SELECT events.id AS events_id, events.title AS events_title, events.date AS events_date, events.location AS events_location, events.address AS events_address, events.categories AS events_categories, events.price AS events_price, events.url AS events_url, events.source AS events_source, events.description AS events_description, events.registration_closes AS events_registration_closes, events.scraped_at AS events_scraped_at, events.image_url AS events_image_url, events.created_at AS events_created_at, events.updated_at AS events_updated_at, events.is_verified AS events_is_verified 
FROM events]
(Background on this error at: https://sqlalche.me/e/20/4xp6)
2025-06-01 12:07:47,662 - app.api.routes - INFO - GET /clubs request from 127.0.0.1
2025-06-01 12:07:53,106 - app.api.routes - INFO - Retrieved 1 clubs from database.
2025-06-01 12:17:33,733 - app.api.routes - INFO - GET /events request from 127.0.0.1
2025-06-01 12:17:37,519 - app.api.routes - INFO - Retrieved 6 events from database.
2025-06-01 12:17:37,528 - app.api.routes - INFO - GET /clubs request from 127.0.0.1
2025-06-01 12:17:38,638 - app.api.routes - INFO - Retrieved 1 clubs from database.
2025-06-01 12:17:57,185 - app.api.routes - INFO - GET /events request from 127.0.0.1
2025-06-01 12:17:57,188 - app.api.routes - ERROR - Error getting events: (psycopg2.DatabaseError) could not receive data from server: Can't assign requested address
SSL SYSCALL error: Can't assign requested address

[SQL: SELECT events.id AS events_id, events.title AS events_title, events.date AS events_date, events.location AS events_location, events.address AS events_address, events.categories AS events_categories, events.price AS events_price, events.url AS events_url, events.source AS events_source, events.description AS events_description, events.registration_closes AS events_registration_closes, events.scraped_at AS events_scraped_at, events.image_url AS events_image_url, events.created_at AS events_created_at, events.updated_at AS events_updated_at, events.is_verified AS events_is_verified 
FROM events]
(Background on this error at: https://sqlalche.me/e/20/4xp6)
Traceback (most recent call last):
  File "/Users/satyamtiwari/running-hub/running-hub/backend/venv/lib/python3.9/site-packages/sqlalchemy/engine/base.py", line 1969, in _exec_single_context
    self.dialect.do_execute(
  File "/Users/satyamtiwari/running-hub/running-hub/backend/venv/lib/python3.9/site-packages/sqlalchemy/engine/default.py", line 922, in do_execute
    cursor.execute(statement, parameters)
psycopg2.DatabaseError: could not receive data from server: Can't assign requested address
SSL SYSCALL error: Can't assign requested address


The above exception was the direct cause of the following exception:

Traceback (most recent call last):
  File "/Users/satyamtiwari/running-hub/running-hub/backend/app/api/routes.py", line 37, in get_events
    events = db.query(EventModel).all()
  File "/Users/satyamtiwari/running-hub/running-hub/backend/venv/lib/python3.9/site-packages/sqlalchemy/orm/query.py", line 2693, in all
    return self._iter().all()  # type: ignore
  File "/Users/satyamtiwari/running-hub/running-hub/backend/venv/lib/python3.9/site-packages/sqlalchemy/orm/query.py", line 2847, in _iter
    result: Union[ScalarResult[_T], Result[_T]] = self.session.execute(
  File "/Users/satyamtiwari/running-hub/running-hub/backend/venv/lib/python3.9/site-packages/sqlalchemy/orm/session.py", line 2308, in execute
    return self._execute_internal(
  File "/Users/satyamtiwari/running-hub/running-hub/backend/venv/lib/python3.9/site-packages/sqlalchemy/orm/session.py", line 2190, in _execute_internal
    result: Result[Any] = compile_state_cls.orm_execute_statement(
  File "/Users/satyamtiwari/running-hub/running-hub/backend/venv/lib/python3.9/site-packages/sqlalchemy/orm/context.py", line 293, in orm_execute_statement
    result = conn.execute(
  File "/Users/satyamtiwari/running-hub/running-hub/backend/venv/lib/python3.9/site-packages/sqlalchemy/engine/base.py", line 1416, in execute
    return meth(
  File "/Users/satyamtiwari/running-hub/running-hub/backend/venv/lib/python3.9/site-packages/sqlalchemy/sql/elements.py", line 516, in _execute_on_connection
    return connection._execute_clauseelement(
  File "/Users/satyamtiwari/running-hub/running-hub/backend/venv/lib/python3.9/site-packages/sqlalchemy/engine/base.py", line 1639, in _execute_clauseelement
    ret = self._execute_context(
  File "/Users/satyamtiwari/running-hub/running-hub/backend/venv/lib/python3.9/site-packages/sqlalchemy/engine/base.py", line 1848, in _execute_context
    return self._exec_single_context(
  File "/Users/satyamtiwari/running-hub/running-hub/backend/venv/lib/python3.9/site-packages/sqlalchemy/engine/base.py", line 1988, in _exec_single_context
    self._handle_dbapi_exception(
  File "/Users/satyamtiwari/running-hub/running-hub/backend/venv/lib/python3.9/site-packages/sqlalchemy/engine/base.py", line 2343, in _handle_dbapi_exception
    raise sqlalchemy_exception.with_traceback(exc_info[2]) from e
  File "/Users/satyamtiwari/running-hub/running-hub/backend/venv/lib/python3.9/site-packages/sqlalchemy/engine/base.py", line 1969, in _exec_single_context
    self.dialect.do_execute(
  File "/Users/satyamtiwari/running-hub/running-hub/backend/venv/lib/python3.9/site-packages/sqlalchemy/engine/default.py", line 922, in do_execute
    cursor.execute(statement, parameters)
sqlalchemy.exc.DatabaseError: (psycopg2.DatabaseError) could not receive data from server: Can't assign requested address
SSL SYSCALL error: Can't assign requested address

[SQL: SELECT events.id AS events_id, events.title AS events_title, events.date AS events_date, events.location AS events_location, events.address AS events_address, events.categories AS events_categories, events.price AS events_price, events.url AS events_url, events.source AS events_source, events.description AS events_description, events.registration_closes AS events_registration_closes, events.scraped_at AS events_scraped_at, events.image_url AS events_image_url, events.created_at AS events_created_at, events.updated_at AS events_updated_at, events.is_verified AS events_is_verified 
FROM events]
(Background on this error at: https://sqlalche.me/e/20/4xp6)
2025-06-01 12:17:57,191 - app.api.routes - INFO - GET /clubs request from 127.0.0.1
2025-06-01 12:17:57,816 - app.api.routes - INFO - Retrieved 1 clubs from database.
2025-06-01 16:39:45,216 - app.api.routes - INFO - GET /events request from 127.0.0.1
2025-06-01 16:39:45,864 - app.api.routes - INFO - Retrieved 6 events from database.
2025-06-01 16:39:45,872 - app.api.routes - INFO - GET /clubs request from 127.0.0.1
2025-06-01 16:39:46,483 - app.api.routes - INFO - Retrieved 1 clubs from database.
2025-06-01 17:17:47,456 - app.api.routes - INFO - GET /events request from 127.0.0.1
2025-06-01 17:17:47,564 - app.api.routes - ERROR - Error getting events: (psycopg2.OperationalError) server closed the connection unexpectedly
	This probably means the server terminated abnormally
	before or while processing the request.
server closed the connection unexpectedly
	This probably means the server terminated abnormally
	before or while processing the request.

[SQL: SELECT events.id AS events_id, events.title AS events_title, events.date AS events_date, events.location AS events_location, events.address AS events_address, events.categories AS events_categories, events.price AS events_price, events.url AS events_url, events.source AS events_source, events.description AS events_description, events.registration_closes AS events_registration_closes, events.scraped_at AS events_scraped_at, events.image_url AS events_image_url, events.created_at AS events_created_at, events.updated_at AS events_updated_at, events.is_verified AS events_is_verified 
FROM events]
(Background on this error at: https://sqlalche.me/e/20/e3q8)
Traceback (most recent call last):
  File "/Users/satyamtiwari/running-hub/running-hub/backend/venv/lib/python3.9/site-packages/sqlalchemy/engine/base.py", line 1969, in _exec_single_context
    self.dialect.do_execute(
  File "/Users/satyamtiwari/running-hub/running-hub/backend/venv/lib/python3.9/site-packages/sqlalchemy/engine/default.py", line 922, in do_execute
    cursor.execute(statement, parameters)
psycopg2.OperationalError: server closed the connection unexpectedly
	This probably means the server terminated abnormally
	before or while processing the request.
server closed the connection unexpectedly
	This probably means the server terminated abnormally
	before or while processing the request.


The above exception was the direct cause of the following exception:

Traceback (most recent call last):
  File "/Users/satyamtiwari/running-hub/running-hub/backend/app/api/routes.py", line 37, in get_events
    events = db.query(EventModel).all()
  File "/Users/satyamtiwari/running-hub/running-hub/backend/venv/lib/python3.9/site-packages/sqlalchemy/orm/query.py", line 2693, in all
    return self._iter().all()  # type: ignore
  File "/Users/satyamtiwari/running-hub/running-hub/backend/venv/lib/python3.9/site-packages/sqlalchemy/orm/query.py", line 2847, in _iter
    result: Union[ScalarResult[_T], Result[_T]] = self.session.execute(
  File "/Users/satyamtiwari/running-hub/running-hub/backend/venv/lib/python3.9/site-packages/sqlalchemy/orm/session.py", line 2308, in execute
    return self._execute_internal(
  File "/Users/satyamtiwari/running-hub/running-hub/backend/venv/lib/python3.9/site-packages/sqlalchemy/orm/session.py", line 2190, in _execute_internal
    result: Result[Any] = compile_state_cls.orm_execute_statement(
  File "/Users/satyamtiwari/running-hub/running-hub/backend/venv/lib/python3.9/site-packages/sqlalchemy/orm/context.py", line 293, in orm_execute_statement
    result = conn.execute(
  File "/Users/satyamtiwari/running-hub/running-hub/backend/venv/lib/python3.9/site-packages/sqlalchemy/engine/base.py", line 1416, in execute
    return meth(
  File "/Users/satyamtiwari/running-hub/running-hub/backend/venv/lib/python3.9/site-packages/sqlalchemy/sql/elements.py", line 516, in _execute_on_connection
    return connection._execute_clauseelement(
  File "/Users/satyamtiwari/running-hub/running-hub/backend/venv/lib/python3.9/site-packages/sqlalchemy/engine/base.py", line 1639, in _execute_clauseelement
    ret = self._execute_context(
  File "/Users/satyamtiwari/running-hub/running-hub/backend/venv/lib/python3.9/site-packages/sqlalchemy/engine/base.py", line 1848, in _execute_context
    return self._exec_single_context(
  File "/Users/satyamtiwari/running-hub/running-hub/backend/venv/lib/python3.9/site-packages/sqlalchemy/engine/base.py", line 1988, in _exec_single_context
    self._handle_dbapi_exception(
  File "/Users/satyamtiwari/running-hub/running-hub/backend/venv/lib/python3.9/site-packages/sqlalchemy/engine/base.py", line 2343, in _handle_dbapi_exception
    raise sqlalchemy_exception.with_traceback(exc_info[2]) from e
  File "/Users/satyamtiwari/running-hub/running-hub/backend/venv/lib/python3.9/site-packages/sqlalchemy/engine/base.py", line 1969, in _exec_single_context
    self.dialect.do_execute(
  File "/Users/satyamtiwari/running-hub/running-hub/backend/venv/lib/python3.9/site-packages/sqlalchemy/engine/default.py", line 922, in do_execute
    cursor.execute(statement, parameters)
sqlalchemy.exc.OperationalError: (psycopg2.OperationalError) server closed the connection unexpectedly
	This probably means the server terminated abnormally
	before or while processing the request.
server closed the connection unexpectedly
	This probably means the server terminated abnormally
	before or while processing the request.

[SQL: SELECT events.id AS events_id, events.title AS events_title, events.date AS events_date, events.location AS events_location, events.address AS events_address, events.categories AS events_categories, events.price AS events_price, events.url AS events_url, events.source AS events_source, events.description AS events_description, events.registration_closes AS events_registration_closes, events.scraped_at AS events_scraped_at, events.image_url AS events_image_url, events.created_at AS events_created_at, events.updated_at AS events_updated_at, events.is_verified AS events_is_verified 
FROM events]
(Background on this error at: https://sqlalche.me/e/20/e3q8)
2025-06-01 17:17:47,579 - app.api.routes - INFO - GET /clubs request from 127.0.0.1
2025-06-01 17:17:48,367 - app.api.routes - INFO - Retrieved 1 clubs from database.
2025-06-01 17:18:14,885 - app.api.routes - INFO - GET /clubs request from 127.0.0.1
2025-06-01 17:18:16,230 - app.api.routes - INFO - Retrieved 1 clubs from database.
2025-06-01 17:19:16,519 - app.api.routes - INFO - GET /clubs request from 127.0.0.1
2025-06-01 17:19:21,483 - app.api.routes - INFO - Retrieved 1 clubs from database.
2025-06-01 17:20:34,426 - app.api.routes - INFO - GET /events request from 127.0.0.1
2025-06-01 17:38:08,458 - app.api.routes - ERROR - Error getting events: (psycopg2.OperationalError) could not receive data from server: No route to host
SSL SYSCALL error: No route to host

[SQL: SELECT events.id AS events_id, events.title AS events_title, events.date AS events_date, events.location AS events_location, events.address AS events_address, events.categories AS events_categories, events.price AS events_price, events.url AS events_url, events.source AS events_source, events.description AS events_description, events.registration_closes AS events_registration_closes, events.scraped_at AS events_scraped_at, events.image_url AS events_image_url, events.created_at AS events_created_at, events.updated_at AS events_updated_at, events.is_verified AS events_is_verified 
FROM events]
(Background on this error at: https://sqlalche.me/e/20/e3q8)
Traceback (most recent call last):
  File "/Users/satyamtiwari/running-hub/running-hub/backend/venv/lib/python3.9/site-packages/sqlalchemy/engine/base.py", line 1969, in _exec_single_context
    self.dialect.do_execute(
  File "/Users/satyamtiwari/running-hub/running-hub/backend/venv/lib/python3.9/site-packages/sqlalchemy/engine/default.py", line 922, in do_execute
    cursor.execute(statement, parameters)
psycopg2.OperationalError: could not receive data from server: No route to host
SSL SYSCALL error: No route to host


The above exception was the direct cause of the following exception:

Traceback (most recent call last):
  File "/Users/satyamtiwari/running-hub/running-hub/backend/app/api/routes.py", line 37, in get_events
    events = db.query(EventModel).all()
  File "/Users/satyamtiwari/running-hub/running-hub/backend/venv/lib/python3.9/site-packages/sqlalchemy/orm/query.py", line 2693, in all
    return self._iter().all()  # type: ignore
  File "/Users/satyamtiwari/running-hub/running-hub/backend/venv/lib/python3.9/site-packages/sqlalchemy/orm/query.py", line 2847, in _iter
    result: Union[ScalarResult[_T], Result[_T]] = self.session.execute(
  File "/Users/satyamtiwari/running-hub/running-hub/backend/venv/lib/python3.9/site-packages/sqlalchemy/orm/session.py", line 2308, in execute
    return self._execute_internal(
  File "/Users/satyamtiwari/running-hub/running-hub/backend/venv/lib/python3.9/site-packages/sqlalchemy/orm/session.py", line 2190, in _execute_internal
    result: Result[Any] = compile_state_cls.orm_execute_statement(
  File "/Users/satyamtiwari/running-hub/running-hub/backend/venv/lib/python3.9/site-packages/sqlalchemy/orm/context.py", line 293, in orm_execute_statement
    result = conn.execute(
  File "/Users/satyamtiwari/running-hub/running-hub/backend/venv/lib/python3.9/site-packages/sqlalchemy/engine/base.py", line 1416, in execute
    return meth(
  File "/Users/satyamtiwari/running-hub/running-hub/backend/venv/lib/python3.9/site-packages/sqlalchemy/sql/elements.py", line 516, in _execute_on_connection
    return connection._execute_clauseelement(
  File "/Users/satyamtiwari/running-hub/running-hub/backend/venv/lib/python3.9/site-packages/sqlalchemy/engine/base.py", line 1639, in _execute_clauseelement
    ret = self._execute_context(
  File "/Users/satyamtiwari/running-hub/running-hub/backend/venv/lib/python3.9/site-packages/sqlalchemy/engine/base.py", line 1848, in _execute_context
    return self._exec_single_context(
  File "/Users/satyamtiwari/running-hub/running-hub/backend/venv/lib/python3.9/site-packages/sqlalchemy/engine/base.py", line 1988, in _exec_single_context
    self._handle_dbapi_exception(
  File "/Users/satyamtiwari/running-hub/running-hub/backend/venv/lib/python3.9/site-packages/sqlalchemy/engine/base.py", line 2343, in _handle_dbapi_exception
    raise sqlalchemy_exception.with_traceback(exc_info[2]) from e
  File "/Users/satyamtiwari/running-hub/running-hub/backend/venv/lib/python3.9/site-packages/sqlalchemy/engine/base.py", line 1969, in _exec_single_context
    self.dialect.do_execute(
  File "/Users/satyamtiwari/running-hub/running-hub/backend/venv/lib/python3.9/site-packages/sqlalchemy/engine/default.py", line 922, in do_execute
    cursor.execute(statement, parameters)
sqlalchemy.exc.OperationalError: (psycopg2.OperationalError) could not receive data from server: No route to host
SSL SYSCALL error: No route to host

[SQL: SELECT events.id AS events_id, events.title AS events_title, events.date AS events_date, events.location AS events_location, events.address AS events_address, events.categories AS events_categories, events.price AS events_price, events.url AS events_url, events.source AS events_source, events.description AS events_description, events.registration_closes AS events_registration_closes, events.scraped_at AS events_scraped_at, events.image_url AS events_image_url, events.created_at AS events_created_at, events.updated_at AS events_updated_at, events.is_verified AS events_is_verified 
FROM events]
(Background on this error at: https://sqlalche.me/e/20/e3q8)
2025-06-01 17:38:08,465 - app.api.routes - INFO - GET /clubs request from 127.0.0.1
2025-06-01 17:38:09,563 - app.api.routes - INFO - Retrieved 1 clubs from database.
2025-06-01 22:12:42,075 - app.api.routes - INFO - GET /clubs request from 127.0.0.1
2025-06-01 22:12:42,720 - app.api.routes - INFO - Retrieved 1 clubs from database.
2025-06-01 22:12:42,728 - app.api.routes - INFO - GET /events request from 127.0.0.1
2025-06-01 22:12:43,283 - app.api.routes - INFO - Retrieved 8 events from database.
2025-06-01 22:13:02,582 - app.api.routes - INFO - GET /events/eaa4f87b-1ab3-436f-8412-fe1f1b32cd0a request from 127.0.0.1
2025-06-01 22:13:02,687 - app.api.routes - ERROR - Error getting event eaa4f87b-1ab3-436f-8412-fe1f1b32cd0a: (psycopg2.OperationalError) server closed the connection unexpectedly
	This probably means the server terminated abnormally
	before or while processing the request.
server closed the connection unexpectedly
	This probably means the server terminated abnormally
	before or while processing the request.

[SQL: SELECT events.id AS events_id, events.title AS events_title, events.date AS events_date, events.location AS events_location, events.address AS events_address, events.categories AS events_categories, events.price AS events_price, events.url AS events_url, events.source AS events_source, events.description AS events_description, events.registration_closes AS events_registration_closes, events.scraped_at AS events_scraped_at, events.image_url AS events_image_url, events.created_at AS events_created_at, events.updated_at AS events_updated_at, events.is_verified AS events_is_verified 
FROM events 
WHERE events.id = %(id_1)s::UUID 
 LIMIT %(param_1)s]
[parameters: {'id_1': 'eaa4f87b-1ab3-436f-8412-fe1f1b32cd0a', 'param_1': 1}]
(Background on this error at: https://sqlalche.me/e/20/e3q8)
Traceback (most recent call last):
  File "/Users/satyamtiwari/running-hub/running-hub/backend/venv/lib/python3.9/site-packages/sqlalchemy/engine/base.py", line 1969, in _exec_single_context
    self.dialect.do_execute(
  File "/Users/satyamtiwari/running-hub/running-hub/backend/venv/lib/python3.9/site-packages/sqlalchemy/engine/default.py", line 922, in do_execute
    cursor.execute(statement, parameters)
psycopg2.OperationalError: server closed the connection unexpectedly
	This probably means the server terminated abnormally
	before or while processing the request.
server closed the connection unexpectedly
	This probably means the server terminated abnormally
	before or while processing the request.


The above exception was the direct cause of the following exception:

Traceback (most recent call last):
  File "/Users/satyamtiwari/running-hub/running-hub/backend/app/api/routes.py", line 70, in get_event
    event = db.query(EventModel).filter(EventModel.id == event_id).first()
  File "/Users/satyamtiwari/running-hub/running-hub/backend/venv/lib/python3.9/site-packages/sqlalchemy/orm/query.py", line 2748, in first
    return self.limit(1)._iter().first()  # type: ignore
  File "/Users/satyamtiwari/running-hub/running-hub/backend/venv/lib/python3.9/site-packages/sqlalchemy/orm/query.py", line 2847, in _iter
    result: Union[ScalarResult[_T], Result[_T]] = self.session.execute(
  File "/Users/satyamtiwari/running-hub/running-hub/backend/venv/lib/python3.9/site-packages/sqlalchemy/orm/session.py", line 2308, in execute
    return self._execute_internal(
  File "/Users/satyamtiwari/running-hub/running-hub/backend/venv/lib/python3.9/site-packages/sqlalchemy/orm/session.py", line 2190, in _execute_internal
    result: Result[Any] = compile_state_cls.orm_execute_statement(
  File "/Users/satyamtiwari/running-hub/running-hub/backend/venv/lib/python3.9/site-packages/sqlalchemy/orm/context.py", line 293, in orm_execute_statement
    result = conn.execute(
  File "/Users/satyamtiwari/running-hub/running-hub/backend/venv/lib/python3.9/site-packages/sqlalchemy/engine/base.py", line 1416, in execute
    return meth(
  File "/Users/satyamtiwari/running-hub/running-hub/backend/venv/lib/python3.9/site-packages/sqlalchemy/sql/elements.py", line 516, in _execute_on_connection
    return connection._execute_clauseelement(
  File "/Users/satyamtiwari/running-hub/running-hub/backend/venv/lib/python3.9/site-packages/sqlalchemy/engine/base.py", line 1639, in _execute_clauseelement
    ret = self._execute_context(
  File "/Users/satyamtiwari/running-hub/running-hub/backend/venv/lib/python3.9/site-packages/sqlalchemy/engine/base.py", line 1848, in _execute_context
    return self._exec_single_context(
  File "/Users/satyamtiwari/running-hub/running-hub/backend/venv/lib/python3.9/site-packages/sqlalchemy/engine/base.py", line 1988, in _exec_single_context
    self._handle_dbapi_exception(
  File "/Users/satyamtiwari/running-hub/running-hub/backend/venv/lib/python3.9/site-packages/sqlalchemy/engine/base.py", line 2343, in _handle_dbapi_exception
    raise sqlalchemy_exception.with_traceback(exc_info[2]) from e
  File "/Users/satyamtiwari/running-hub/running-hub/backend/venv/lib/python3.9/site-packages/sqlalchemy/engine/base.py", line 1969, in _exec_single_context
    self.dialect.do_execute(
  File "/Users/satyamtiwari/running-hub/running-hub/backend/venv/lib/python3.9/site-packages/sqlalchemy/engine/default.py", line 922, in do_execute
    cursor.execute(statement, parameters)
sqlalchemy.exc.OperationalError: (psycopg2.OperationalError) server closed the connection unexpectedly
	This probably means the server terminated abnormally
	before or while processing the request.
server closed the connection unexpectedly
	This probably means the server terminated abnormally
	before or while processing the request.

[SQL: SELECT events.id AS events_id, events.title AS events_title, events.date AS events_date, events.location AS events_location, events.address AS events_address, events.categories AS events_categories, events.price AS events_price, events.url AS events_url, events.source AS events_source, events.description AS events_description, events.registration_closes AS events_registration_closes, events.scraped_at AS events_scraped_at, events.image_url AS events_image_url, events.created_at AS events_created_at, events.updated_at AS events_updated_at, events.is_verified AS events_is_verified 
FROM events 
WHERE events.id = %(id_1)s::UUID 
 LIMIT %(param_1)s]
[parameters: {'id_1': 'eaa4f87b-1ab3-436f-8412-fe1f1b32cd0a', 'param_1': 1}]
(Background on this error at: https://sqlalche.me/e/20/e3q8)
2025-06-01 22:13:03,694 - app.api.routes - INFO - GET /events/eaa4f87b-1ab3-436f-8412-fe1f1b32cd0a request from 127.0.0.1
2025-06-01 22:13:04,328 - app.api.routes - INFO - Retrieved event with ID: eaa4f87b-1ab3-436f-8412-fe1f1b32cd0a
2025-06-01 22:13:11,105 - app.api.routes - INFO - GET /events request from 127.0.0.1
2025-06-01 22:13:11,734 - app.api.routes - INFO - Retrieved 8 events from database.
2025-06-01 22:13:12,830 - app.api.routes - INFO - GET /events request from 127.0.0.1
2025-06-01 22:13:13,466 - app.api.routes - INFO - Retrieved 8 events from database.
2025-06-01 22:13:13,467 - app.api.routes - INFO - GET /clubs request from 127.0.0.1
2025-06-01 22:13:13,612 - app.api.routes - INFO - Retrieved 1 clubs from database.
2025-06-01 22:14:51,477 - app.api.routes - INFO - GET /events request from 127.0.0.1
2025-06-01 22:14:51,655 - app.api.routes - INFO - Retrieved 8 events from database.
2025-06-01 22:14:51,671 - app.api.routes - INFO - GET /clubs request from 127.0.0.1
2025-06-01 22:14:51,823 - app.api.routes - INFO - Retrieved 1 clubs from database.
2025-06-01 22:16:11,858 - app.api.routes - INFO - GET /events request from 127.0.0.1
2025-06-01 22:16:12,033 - app.api.routes - INFO - Retrieved 8 events from database.
2025-06-01 22:16:12,053 - app.api.routes - INFO - GET /clubs request from 127.0.0.1
2025-06-01 22:16:12,200 - app.api.routes - INFO - Retrieved 1 clubs from database.
2025-06-01 22:16:34,207 - app.api.routes - INFO - GET /events request from 127.0.0.1
2025-06-01 22:16:34,407 - app.api.routes - INFO - Retrieved 8 events from database.
2025-06-01 22:16:34,409 - app.api.routes - INFO - GET /clubs request from 127.0.0.1
2025-06-01 22:16:34,554 - app.api.routes - INFO - Retrieved 1 clubs from database.
2025-06-01 22:21:38,179 - app.api.routes - INFO - GET /events request from 127.0.0.1
2025-06-01 22:21:38,472 - app.api.routes - INFO - Retrieved 68 events from database.
2025-06-01 22:21:38,490 - app.api.routes - INFO - GET /clubs request from 127.0.0.1
2025-06-01 22:21:38,637 - app.api.routes - INFO - Retrieved 1 clubs from database.
2025-06-01 22:21:39,723 - app.api.routes - INFO - GET /events request from 127.0.0.1
2025-06-01 22:21:39,950 - app.api.routes - INFO - Retrieved 68 events from database.
2025-06-01 22:21:42,029 - app.api.routes - INFO - GET /events request from 127.0.0.1
2025-06-01 22:21:42,293 - app.api.routes - INFO - Retrieved 68 events from database.
2025-06-01 22:21:46,379 - app.api.routes - INFO - GET /events request from 127.0.0.1
2025-06-01 22:21:46,667 - app.api.routes - INFO - Retrieved 68 events from database.
2025-06-01 22:21:49,583 - app.api.routes - INFO - GET /events request from 127.0.0.1
2025-06-01 22:21:49,814 - app.api.routes - INFO - Retrieved 68 events from database.
2025-06-01 22:21:49,815 - app.api.routes - INFO - GET /clubs request from 127.0.0.1
2025-06-01 22:21:49,962 - app.api.routes - INFO - Retrieved 1 clubs from database.
2025-06-01 22:21:51,054 - app.api.routes - INFO - GET /events request from 127.0.0.1
2025-06-01 22:21:51,283 - app.api.routes - INFO - Retrieved 68 events from database.
2025-06-01 22:21:53,367 - app.api.routes - INFO - GET /events request from 127.0.0.1
2025-06-01 22:21:53,843 - app.api.routes - INFO - Retrieved 68 events from database.
2025-06-01 22:21:57,929 - app.api.routes - INFO - GET /events request from 127.0.0.1
2025-06-01 22:21:58,158 - app.api.routes - INFO - Retrieved 68 events from database.
2025-06-01 22:22:06,932 - app.api.routes - INFO - GET /events request from 127.0.0.1
2025-06-01 22:22:07,180 - app.api.routes - INFO - Retrieved 68 events from database.
2025-06-01 22:22:07,181 - app.api.routes - INFO - GET /clubs request from 127.0.0.1
2025-06-01 22:22:07,330 - app.api.routes - INFO - Retrieved 1 clubs from database.
2025-06-01 22:22:08,339 - app.api.routes - INFO - GET /events request from 127.0.0.1
2025-06-01 22:22:08,689 - app.api.routes - INFO - Retrieved 68 events from database.
2025-06-01 22:22:09,771 - app.api.routes - INFO - GET /events request from 127.0.0.1
2025-06-01 22:22:09,994 - app.api.routes - INFO - Retrieved 68 events from database.
2025-06-01 22:22:12,070 - app.api.routes - INFO - GET /events request from 127.0.0.1
2025-06-01 22:22:12,552 - app.api.routes - INFO - Retrieved 68 events from database.
2025-06-01 22:22:16,637 - app.api.routes - INFO - GET /events request from 127.0.0.1
2025-06-01 22:22:16,974 - app.api.routes - INFO - Retrieved 68 events from database.
2025-06-01 22:25:24,062 - app.api.routes - INFO - GET /events request from 127.0.0.1
2025-06-01 22:25:24,311 - app.api.routes - INFO - Retrieved 68 events from database.
2025-06-01 22:25:25,394 - app.api.routes - INFO - GET /events request from 127.0.0.1
2025-06-01 22:25:25,629 - app.api.routes - INFO - Retrieved 68 events from database.
2025-06-01 22:25:25,881 - app.api.routes - INFO - GET /events request from 127.0.0.1
2025-06-01 22:25:26,103 - app.api.routes - INFO - Retrieved 68 events from database.
2025-06-01 22:25:26,105 - app.api.routes - INFO - GET /clubs request from 127.0.0.1
2025-06-01 22:25:26,251 - app.api.routes - INFO - Retrieved 1 clubs from database.
2025-06-01 22:25:27,337 - app.api.routes - INFO - GET /events request from 127.0.0.1
2025-06-01 22:25:27,564 - app.api.routes - INFO - Retrieved 68 events from database.
2025-06-01 22:25:29,646 - app.api.routes - INFO - GET /events request from 127.0.0.1
2025-06-01 22:25:30,135 - app.api.routes - INFO - Retrieved 68 events from database.
2025-06-01 22:25:32,525 - app.api.routes - INFO - GET /events request from 127.0.0.1
2025-06-01 22:25:32,750 - app.api.routes - INFO - Retrieved 68 events from database.
2025-06-01 22:25:32,751 - app.api.routes - INFO - GET /clubs request from 127.0.0.1
2025-06-01 22:25:32,902 - app.api.routes - INFO - Retrieved 1 clubs from database.
2025-06-01 22:25:33,981 - app.api.routes - INFO - GET /events request from 127.0.0.1
2025-06-01 22:25:34,435 - app.api.routes - INFO - Retrieved 68 events from database.
2025-06-01 22:25:36,516 - app.api.routes - INFO - GET /events request from 127.0.0.1
2025-06-01 22:25:36,743 - app.api.routes - INFO - Retrieved 68 events from database.
2025-06-01 22:27:31,557 - app.api.routes - INFO - GET /clubs request from 127.0.0.1
2025-06-01 22:27:31,813 - app.api.routes - INFO - Retrieved 1 clubs from database.
2025-06-01 22:27:31,829 - app.api.routes - INFO - GET /events request from 127.0.0.1
2025-06-01 22:27:32,052 - app.api.routes - INFO - Retrieved 68 events from database.
2025-06-01 22:27:55,665 - app.api.routes - INFO - GET /events request from 127.0.0.1
2025-06-01 22:27:55,916 - app.api.routes - INFO - Retrieved 68 events from database.
2025-06-01 22:27:59,204 - app.api.routes - INFO - GET /events request from 127.0.0.1
2025-06-01 22:27:59,428 - app.api.routes - INFO - Retrieved 68 events from database.
2025-06-01 22:28:38,629 - app.api.routes - INFO - GET /events request from 127.0.0.1
2025-06-01 22:28:38,895 - app.api.routes - INFO - Retrieved 68 events from database.
2025-06-01 22:33:56,812 - app.api.routes - INFO - GET /events request from 127.0.0.1
2025-06-01 22:33:57,064 - app.api.routes - INFO - Retrieved 68 events from database.
2025-06-01 22:34:00,918 - app.api.routes - INFO - GET /events request from 127.0.0.1
2025-06-01 22:34:01,145 - app.api.routes - INFO - Retrieved 68 events from database.
2025-06-01 22:37:51,365 - app.api.routes - INFO - GET /events request from 127.0.0.1
2025-06-01 22:37:51,600 - app.api.routes - INFO - Retrieved 68 events from database.
2025-06-01 22:38:02,498 - app.api.routes - INFO - GET /events request from 127.0.0.1
2025-06-01 22:38:02,730 - app.api.routes - INFO - Retrieved 68 events from database.
2025-06-01 22:38:02,734 - app.api.routes - INFO - GET /clubs request from 127.0.0.1
2025-06-01 22:38:02,884 - app.api.routes - INFO - Retrieved 1 clubs from database.
2025-06-01 22:38:15,976 - app.api.routes - INFO - GET /events request from 127.0.0.1
2025-06-01 22:38:16,204 - app.api.routes - INFO - Retrieved 68 events from database.
2025-06-01 22:38:19,558 - app.api.routes - INFO - GET /events request from 127.0.0.1
2025-06-01 22:38:19,781 - app.api.routes - INFO - Retrieved 68 events from database.
2025-06-01 22:38:19,787 - app.api.routes - INFO - GET /clubs request from 127.0.0.1
2025-06-01 22:38:19,939 - app.api.routes - INFO - Retrieved 1 clubs from database.
2025-06-01 22:38:47,088 - app.api.routes - INFO - GET /events request from 127.0.0.1
2025-06-01 22:38:47,321 - app.api.routes - INFO - Retrieved 68 events from database.
2025-06-01 22:38:47,323 - app.api.routes - INFO - GET /clubs request from 127.0.0.1
2025-06-01 22:38:47,471 - app.api.routes - INFO - Retrieved 1 clubs from database.
2025-06-01 22:42:35,102 - app.api.routes - INFO - GET /events request from 127.0.0.1
2025-06-01 22:42:35,333 - app.api.routes - INFO - Retrieved 68 events from database.
2025-06-01 22:42:35,335 - app.api.routes - INFO - GET /clubs request from 127.0.0.1
2025-06-01 22:42:35,481 - app.api.routes - INFO - Retrieved 1 clubs from database.
2025-06-01 22:46:30,717 - app.api.routes - INFO - GET /events request from 127.0.0.1
2025-06-01 22:46:30,983 - app.api.routes - INFO - Retrieved 68 events from database.
2025-06-01 22:46:30,996 - app.api.routes - INFO - GET /clubs request from 127.0.0.1
2025-06-01 22:46:31,152 - app.api.routes - INFO - Retrieved 1 clubs from database.
2025-06-01 22:46:37,967 - app.api.routes - INFO - GET /events request from 127.0.0.1
2025-06-01 22:46:38,217 - app.api.routes - INFO - Retrieved 68 events from database.
2025-06-01 22:46:38,221 - app.api.routes - INFO - GET /clubs request from 127.0.0.1
2025-06-01 22:46:38,371 - app.api.routes - INFO - Retrieved 1 clubs from database.
2025-06-01 22:47:42,002 - app.api.routes - INFO - GET /events request from 127.0.0.1
2025-06-01 22:47:42,328 - app.api.routes - INFO - Retrieved 68 events from database.
2025-06-01 22:47:42,337 - app.api.routes - INFO - GET /clubs request from 127.0.0.1
2025-06-01 22:47:42,486 - app.api.routes - INFO - Retrieved 1 clubs from database.
2025-06-01 22:47:49,389 - app.api.routes - INFO - GET /events request from 127.0.0.1
2025-06-01 22:47:49,628 - app.api.routes - INFO - Retrieved 68 events from database.
2025-06-01 22:47:49,630 - app.api.routes - INFO - GET /clubs request from 127.0.0.1
2025-06-01 22:47:49,781 - app.api.routes - INFO - Retrieved 1 clubs from database.
2025-06-01 22:48:33,515 - app.api.routes - INFO - GET /events request from 127.0.0.1
2025-06-01 22:48:33,753 - app.api.routes - INFO - Retrieved 68 events from database.
2025-06-01 22:48:33,761 - app.api.routes - INFO - GET /clubs request from 127.0.0.1
2025-06-01 22:48:33,916 - app.api.routes - INFO - Retrieved 1 clubs from database.
2025-06-01 22:48:48,014 - app.api.routes - INFO - GET /events request from 127.0.0.1
2025-06-01 22:48:48,252 - app.api.routes - INFO - Retrieved 68 events from database.
2025-06-01 22:48:48,256 - app.api.routes - INFO - GET /clubs request from 127.0.0.1
2025-06-01 22:48:48,418 - app.api.routes - INFO - Retrieved 1 clubs from database.
2025-06-01 22:49:31,665 - app.api.routes - INFO - GET /events request from 127.0.0.1
2025-06-01 22:49:31,907 - app.api.routes - INFO - Retrieved 68 events from database.
2025-06-01 22:49:31,915 - app.api.routes - INFO - GET /clubs request from 127.0.0.1
2025-06-01 22:49:32,064 - app.api.routes - INFO - Retrieved 1 clubs from database.
2025-06-01 22:49:59,683 - app.api.routes - INFO - GET /events request from 127.0.0.1
2025-06-01 22:49:59,921 - app.api.routes - INFO - Retrieved 68 events from database.
2025-06-01 22:49:59,924 - app.api.routes - INFO - GET /clubs request from 127.0.0.1
2025-06-01 22:50:00,076 - app.api.routes - INFO - Retrieved 1 clubs from database.
2025-06-01 22:50:02,753 - app.api.routes - INFO - GET /clubs request from 127.0.0.1
2025-06-01 22:50:02,902 - app.api.routes - INFO - Retrieved 1 clubs from database.
2025-06-01 22:50:02,903 - app.api.routes - INFO - GET /events request from 127.0.0.1
2025-06-01 22:50:03,131 - app.api.routes - INFO - Retrieved 68 events from database.
2025-06-01 22:51:08,649 - app.api.routes - INFO - GET /events request from 127.0.0.1
2025-06-01 22:51:08,890 - app.api.routes - INFO - Retrieved 68 events from database.
2025-06-01 22:51:08,892 - app.api.routes - INFO - GET /clubs request from 127.0.0.1
2025-06-01 22:51:09,043 - app.api.routes - INFO - Retrieved 1 clubs from database.
2025-06-01 22:51:13,551 - app.api.routes - INFO - GET /events request from 127.0.0.1
2025-06-01 22:51:13,834 - app.api.routes - INFO - Retrieved 68 events from database.
2025-06-01 22:51:13,946 - app.api.routes - INFO - GET /clubs request from 127.0.0.1
2025-06-01 22:51:14,138 - app.api.routes - INFO - Retrieved 1 clubs from database.
2025-06-01 22:51:16,065 - app.api.routes - INFO - GET /events request from 127.0.0.1
2025-06-01 22:51:16,297 - app.api.routes - INFO - Retrieved 68 events from database.
2025-06-01 22:51:16,300 - app.api.routes - INFO - GET /clubs request from 127.0.0.1
2025-06-01 22:51:16,448 - app.api.routes - INFO - Retrieved 1 clubs from database.
2025-06-01 22:51:41,833 - app.api.routes - INFO - GET /events request from 127.0.0.1
2025-06-01 22:51:42,116 - app.api.routes - INFO - Retrieved 68 events from database.
2025-06-01 22:51:42,128 - app.api.routes - INFO - GET /clubs request from 127.0.0.1
2025-06-01 22:51:42,280 - app.api.routes - INFO - Retrieved 1 clubs from database.
2025-06-01 22:52:06,656 - app.api.routes - INFO - GET /events request from 127.0.0.1
2025-06-01 22:52:06,889 - app.api.routes - INFO - Retrieved 68 events from database.
2025-06-01 22:52:06,894 - app.api.routes - INFO - GET /clubs request from 127.0.0.1
2025-06-01 22:52:07,045 - app.api.routes - INFO - Retrieved 1 clubs from database.
2025-06-01 22:52:17,710 - app.api.routes - INFO - GET /events request from 127.0.0.1
2025-06-01 22:52:17,965 - app.api.routes - INFO - Retrieved 68 events from database.
2025-06-01 22:52:17,972 - app.api.routes - INFO - GET /clubs request from 127.0.0.1
2025-06-01 22:52:18,121 - app.api.routes - INFO - Retrieved 1 clubs from database.
2025-06-01 22:54:18,454 - app.api.routes - INFO - GET /events request from 127.0.0.1
2025-06-01 22:54:18,955 - app.api.routes - INFO - Retrieved 68 events from database.
2025-06-01 22:54:18,969 - app.api.routes - INFO - GET /clubs request from 127.0.0.1
2025-06-01 22:54:19,116 - app.api.routes - INFO - Retrieved 1 clubs from database.
2025-06-01 22:57:44,665 - app.api.routes - INFO - GET /events request from 127.0.0.1
2025-06-01 22:57:44,916 - app.api.routes - INFO - Retrieved 68 events from database.
2025-06-01 22:57:44,927 - app.api.routes - INFO - GET /clubs request from 127.0.0.1
2025-06-01 22:57:45,077 - app.api.routes - INFO - Retrieved 1 clubs from database.
2025-06-01 22:58:07,147 - app.api.routes - INFO - GET /events request from 127.0.0.1
2025-06-01 22:58:07,390 - app.api.routes - INFO - Retrieved 68 events from database.
2025-06-01 22:58:07,399 - app.api.routes - INFO - GET /clubs request from 127.0.0.1
2025-06-01 22:58:07,548 - app.api.routes - INFO - Retrieved 1 clubs from database.
2025-06-01 22:58:11,016 - app.api.routes - INFO - GET /events request from 127.0.0.1
2025-06-01 22:58:11,259 - app.api.routes - INFO - Retrieved 68 events from database.
2025-06-01 22:58:11,261 - app.api.routes - INFO - GET /clubs request from 127.0.0.1
2025-06-01 22:58:11,411 - app.api.routes - INFO - Retrieved 1 clubs from database.
2025-06-01 23:00:11,926 - app.api.routes - INFO - GET /events request from 127.0.0.1
2025-06-01 23:00:12,446 - app.api.routes - INFO - Retrieved 68 events from database.
2025-06-01 23:00:12,449 - app.api.routes - INFO - GET /clubs request from 127.0.0.1
2025-06-01 23:00:12,598 - app.api.routes - INFO - Retrieved 1 clubs from database.
2025-06-01 23:00:19,075 - app.api.routes - INFO - GET /events request from 127.0.0.1
2025-06-01 23:00:19,316 - app.api.routes - INFO - Retrieved 68 events from database.
2025-06-01 23:00:19,318 - app.api.routes - INFO - GET /clubs request from 127.0.0.1
2025-06-01 23:00:19,472 - app.api.routes - INFO - Retrieved 1 clubs from database.
2025-06-01 23:00:51,745 - app.api.routes - INFO - GET /events request from 127.0.0.1
2025-06-01 23:00:51,975 - app.api.routes - INFO - Retrieved 68 events from database.
2025-06-01 23:00:51,978 - app.api.routes - INFO - GET /clubs request from 127.0.0.1
2025-06-01 23:00:52,127 - app.api.routes - INFO - Retrieved 1 clubs from database.
2025-06-01 23:01:08,798 - app.api.routes - INFO - GET /events request from 127.0.0.1
2025-06-01 23:01:09,043 - app.api.routes - INFO - Retrieved 68 events from database.
2025-06-01 23:01:09,047 - app.api.routes - INFO - GET /clubs request from 127.0.0.1
2025-06-01 23:01:09,198 - app.api.routes - INFO - Retrieved 1 clubs from database.
2025-06-01 23:02:11,695 - app.api.routes - INFO - GET /events request from 127.0.0.1
2025-06-01 23:02:11,929 - app.api.routes - INFO - Retrieved 68 events from database.
2025-06-01 23:02:11,937 - app.api.routes - INFO - GET /clubs request from 127.0.0.1
2025-06-01 23:02:12,088 - app.api.routes - INFO - Retrieved 1 clubs from database.
2025-06-01 23:04:54,579 - app.api.routes - INFO - GET /events request from 127.0.0.1
2025-06-01 23:04:54,865 - app.api.routes - INFO - Retrieved 68 events from database.
2025-06-01 23:04:54,882 - app.api.routes - INFO - GET /clubs request from 127.0.0.1
2025-06-01 23:04:55,034 - app.api.routes - INFO - Retrieved 1 clubs from database.
2025-06-01 23:05:00,764 - app.api.routes - INFO - GET /events request from 127.0.0.1
2025-06-01 23:05:00,996 - app.api.routes - INFO - Retrieved 68 events from database.
2025-06-01 23:05:01,000 - app.api.routes - INFO - GET /clubs request from 127.0.0.1
2025-06-01 23:05:01,151 - app.api.routes - INFO - Retrieved 1 clubs from database.
2025-06-01 23:07:47,124 - app.api.routes - INFO - GET /events request from 127.0.0.1
2025-06-01 23:07:47,636 - app.api.routes - INFO - Retrieved 68 events from database.
2025-06-01 23:07:47,646 - app.api.routes - INFO - GET /clubs request from 127.0.0.1
2025-06-01 23:07:47,798 - app.api.routes - INFO - Retrieved 1 clubs from database.
