2025-06-02 00:01:35,415 - app.api.routes - INFO - GET /events request from 127.0.0.1
2025-06-02 00:52:03,170 - app.api.routes - ERROR - Error fetching events: (psycopg2.OperationalError) could not receive data from server: No route to host
SSL SYSCALL error: No route to host

[SQL: SELECT events.id AS events_id, events.title AS events_title, events.date AS events_date, events.location AS events_location, events.address AS events_address, events.categories AS events_categories, events.price AS events_price, events.url AS events_url, events.source AS events_source, events.description AS events_description, events.registration_closes AS events_registration_closes, events.scraped_at AS events_scraped_at, events.image_url AS events_image_url, events.created_at AS events_created_at, events.updated_at AS events_updated_at, events.is_verified AS events_is_verified 
FROM events]
(Background on this error at: https://sqlalche.me/e/20/e3q8)
2025-06-02 00:52:03,175 - app.api.routes - INFO - GET /clubs request from 127.0.0.1
2025-06-02 00:52:03,180 - app.api.routes - ERROR - Error getting clubs: (psycopg2.OperationalError) could not translate host name "ep-small-unit-a1h4gsi7-pooler.ap-southeast-1.aws.neon.tech" to address: nodename nor servname provided, or not known

(Background on this error at: https://sqlalche.me/e/20/e3q8)
Traceback (most recent call last):
  File "/Users/satyamtiwari/running-hub/running-hub/backend/venv/lib/python3.9/site-packages/sqlalchemy/engine/base.py", line 145, in __init__
    self._dbapi_connection = engine.raw_connection()
  File "/Users/satyamtiwari/running-hub/running-hub/backend/venv/lib/python3.9/site-packages/sqlalchemy/engine/base.py", line 3292, in raw_connection
    return self.pool.connect()
  File "/Users/satyamtiwari/running-hub/running-hub/backend/venv/lib/python3.9/site-packages/sqlalchemy/pool/base.py", line 452, in connect
    return _ConnectionFairy._checkout(self)
  File "/Users/satyamtiwari/running-hub/running-hub/backend/venv/lib/python3.9/site-packages/sqlalchemy/pool/base.py", line 1269, in _checkout
    fairy = _ConnectionRecord.checkout(pool)
  File "/Users/satyamtiwari/running-hub/running-hub/backend/venv/lib/python3.9/site-packages/sqlalchemy/pool/base.py", line 722, in checkout
    rec._checkin_failed(err, _fairy_was_created=False)
  File "/Users/satyamtiwari/running-hub/running-hub/backend/venv/lib/python3.9/site-packages/sqlalchemy/util/langhelpers.py", line 146, in __exit__
    raise exc_value.with_traceback(exc_tb)
  File "/Users/satyamtiwari/running-hub/running-hub/backend/venv/lib/python3.9/site-packages/sqlalchemy/pool/base.py", line 719, in checkout
    dbapi_connection = rec.get_connection()
  File "/Users/satyamtiwari/running-hub/running-hub/backend/venv/lib/python3.9/site-packages/sqlalchemy/pool/base.py", line 868, in get_connection
    self.__connect()
  File "/Users/satyamtiwari/running-hub/running-hub/backend/venv/lib/python3.9/site-packages/sqlalchemy/pool/base.py", line 903, in __connect
    pool.logger.debug("Error on connect(): %s", e)
  File "/Users/satyamtiwari/running-hub/running-hub/backend/venv/lib/python3.9/site-packages/sqlalchemy/util/langhelpers.py", line 146, in __exit__
    raise exc_value.with_traceback(exc_tb)
  File "/Users/satyamtiwari/running-hub/running-hub/backend/venv/lib/python3.9/site-packages/sqlalchemy/pool/base.py", line 898, in __connect
    self.dbapi_connection = connection = pool._invoke_creator(self)
  File "/Users/satyamtiwari/running-hub/running-hub/backend/venv/lib/python3.9/site-packages/sqlalchemy/engine/create.py", line 637, in connect
    return dialect.connect(*cargs, **cparams)
  File "/Users/satyamtiwari/running-hub/running-hub/backend/venv/lib/python3.9/site-packages/sqlalchemy/engine/default.py", line 616, in connect
    return self.loaded_dbapi.connect(*cargs, **cparams)
  File "/Users/satyamtiwari/running-hub/running-hub/backend/venv/lib/python3.9/site-packages/psycopg2/__init__.py", line 122, in connect
    conn = _connect(dsn, connection_factory=connection_factory, **kwasync)
psycopg2.OperationalError: could not translate host name "ep-small-unit-a1h4gsi7-pooler.ap-southeast-1.aws.neon.tech" to address: nodename nor servname provided, or not known


The above exception was the direct cause of the following exception:

Traceback (most recent call last):
  File "/Users/satyamtiwari/running-hub/running-hub/backend/app/api/routes.py", line 108, in get_clubs
    clubs = db.query(ClubModel).all()
  File "/Users/satyamtiwari/running-hub/running-hub/backend/venv/lib/python3.9/site-packages/sqlalchemy/orm/query.py", line 2693, in all
    return self._iter().all()  # type: ignore
  File "/Users/satyamtiwari/running-hub/running-hub/backend/venv/lib/python3.9/site-packages/sqlalchemy/orm/query.py", line 2847, in _iter
    result: Union[ScalarResult[_T], Result[_T]] = self.session.execute(
  File "/Users/satyamtiwari/running-hub/running-hub/backend/venv/lib/python3.9/site-packages/sqlalchemy/orm/session.py", line 2308, in execute
    return self._execute_internal(
  File "/Users/satyamtiwari/running-hub/running-hub/backend/venv/lib/python3.9/site-packages/sqlalchemy/orm/session.py", line 2180, in _execute_internal
    conn = self._connection_for_bind(bind)
  File "/Users/satyamtiwari/running-hub/running-hub/backend/venv/lib/python3.9/site-packages/sqlalchemy/orm/session.py", line 2047, in _connection_for_bind
    return trans._connection_for_bind(engine, execution_options)
  File "<string>", line 2, in _connection_for_bind
  File "/Users/satyamtiwari/running-hub/running-hub/backend/venv/lib/python3.9/site-packages/sqlalchemy/orm/state_changes.py", line 139, in _go
    ret_value = fn(self, *arg, **kw)
  File "/Users/satyamtiwari/running-hub/running-hub/backend/venv/lib/python3.9/site-packages/sqlalchemy/orm/session.py", line 1143, in _connection_for_bind
    conn = bind.connect()
  File "/Users/satyamtiwari/running-hub/running-hub/backend/venv/lib/python3.9/site-packages/sqlalchemy/engine/base.py", line 3268, in connect
    return self._connection_cls(self)
  File "/Users/satyamtiwari/running-hub/running-hub/backend/venv/lib/python3.9/site-packages/sqlalchemy/engine/base.py", line 147, in __init__
    Connection._handle_dbapi_exception_noconnection(
  File "/Users/satyamtiwari/running-hub/running-hub/backend/venv/lib/python3.9/site-packages/sqlalchemy/engine/base.py", line 2430, in _handle_dbapi_exception_noconnection
    raise sqlalchemy_exception.with_traceback(exc_info[2]) from e
  File "/Users/satyamtiwari/running-hub/running-hub/backend/venv/lib/python3.9/site-packages/sqlalchemy/engine/base.py", line 145, in __init__
    self._dbapi_connection = engine.raw_connection()
  File "/Users/satyamtiwari/running-hub/running-hub/backend/venv/lib/python3.9/site-packages/sqlalchemy/engine/base.py", line 3292, in raw_connection
    return self.pool.connect()
  File "/Users/satyamtiwari/running-hub/running-hub/backend/venv/lib/python3.9/site-packages/sqlalchemy/pool/base.py", line 452, in connect
    return _ConnectionFairy._checkout(self)
  File "/Users/satyamtiwari/running-hub/running-hub/backend/venv/lib/python3.9/site-packages/sqlalchemy/pool/base.py", line 1269, in _checkout
    fairy = _ConnectionRecord.checkout(pool)
  File "/Users/satyamtiwari/running-hub/running-hub/backend/venv/lib/python3.9/site-packages/sqlalchemy/pool/base.py", line 722, in checkout
    rec._checkin_failed(err, _fairy_was_created=False)
  File "/Users/satyamtiwari/running-hub/running-hub/backend/venv/lib/python3.9/site-packages/sqlalchemy/util/langhelpers.py", line 146, in __exit__
    raise exc_value.with_traceback(exc_tb)
  File "/Users/satyamtiwari/running-hub/running-hub/backend/venv/lib/python3.9/site-packages/sqlalchemy/pool/base.py", line 719, in checkout
    dbapi_connection = rec.get_connection()
  File "/Users/satyamtiwari/running-hub/running-hub/backend/venv/lib/python3.9/site-packages/sqlalchemy/pool/base.py", line 868, in get_connection
    self.__connect()
  File "/Users/satyamtiwari/running-hub/running-hub/backend/venv/lib/python3.9/site-packages/sqlalchemy/pool/base.py", line 903, in __connect
    pool.logger.debug("Error on connect(): %s", e)
  File "/Users/satyamtiwari/running-hub/running-hub/backend/venv/lib/python3.9/site-packages/sqlalchemy/util/langhelpers.py", line 146, in __exit__
    raise exc_value.with_traceback(exc_tb)
  File "/Users/satyamtiwari/running-hub/running-hub/backend/venv/lib/python3.9/site-packages/sqlalchemy/pool/base.py", line 898, in __connect
    self.dbapi_connection = connection = pool._invoke_creator(self)
  File "/Users/satyamtiwari/running-hub/running-hub/backend/venv/lib/python3.9/site-packages/sqlalchemy/engine/create.py", line 637, in connect
    return dialect.connect(*cargs, **cparams)
  File "/Users/satyamtiwari/running-hub/running-hub/backend/venv/lib/python3.9/site-packages/sqlalchemy/engine/default.py", line 616, in connect
    return self.loaded_dbapi.connect(*cargs, **cparams)
  File "/Users/satyamtiwari/running-hub/running-hub/backend/venv/lib/python3.9/site-packages/psycopg2/__init__.py", line 122, in connect
    conn = _connect(dsn, connection_factory=connection_factory, **kwasync)
sqlalchemy.exc.OperationalError: (psycopg2.OperationalError) could not translate host name "ep-small-unit-a1h4gsi7-pooler.ap-southeast-1.aws.neon.tech" to address: nodename nor servname provided, or not known

(Background on this error at: https://sqlalche.me/e/20/e3q8)
2025-06-02 00:52:03,220 - app.api.routes - INFO - GET /events request from 127.0.0.1
2025-06-02 00:52:03,223 - app.api.routes - ERROR - Error fetching events: (psycopg2.OperationalError) could not translate host name "ep-small-unit-a1h4gsi7-pooler.ap-southeast-1.aws.neon.tech" to address: nodename nor servname provided, or not known

(Background on this error at: https://sqlalche.me/e/20/e3q8)
2025-06-02 00:52:03,223 - app.api.routes - INFO - GET /clubs request from 127.0.0.1
2025-06-02 00:52:03,224 - app.api.routes - ERROR - Error getting clubs: (psycopg2.OperationalError) could not translate host name "ep-small-unit-a1h4gsi7-pooler.ap-southeast-1.aws.neon.tech" to address: nodename nor servname provided, or not known

(Background on this error at: https://sqlalche.me/e/20/e3q8)
Traceback (most recent call last):
  File "/Users/satyamtiwari/running-hub/running-hub/backend/venv/lib/python3.9/site-packages/sqlalchemy/engine/base.py", line 145, in __init__
    self._dbapi_connection = engine.raw_connection()
  File "/Users/satyamtiwari/running-hub/running-hub/backend/venv/lib/python3.9/site-packages/sqlalchemy/engine/base.py", line 3292, in raw_connection
    return self.pool.connect()
  File "/Users/satyamtiwari/running-hub/running-hub/backend/venv/lib/python3.9/site-packages/sqlalchemy/pool/base.py", line 452, in connect
    return _ConnectionFairy._checkout(self)
  File "/Users/satyamtiwari/running-hub/running-hub/backend/venv/lib/python3.9/site-packages/sqlalchemy/pool/base.py", line 1269, in _checkout
    fairy = _ConnectionRecord.checkout(pool)
  File "/Users/satyamtiwari/running-hub/running-hub/backend/venv/lib/python3.9/site-packages/sqlalchemy/pool/base.py", line 722, in checkout
    rec._checkin_failed(err, _fairy_was_created=False)
  File "/Users/satyamtiwari/running-hub/running-hub/backend/venv/lib/python3.9/site-packages/sqlalchemy/util/langhelpers.py", line 146, in __exit__
    raise exc_value.with_traceback(exc_tb)
  File "/Users/satyamtiwari/running-hub/running-hub/backend/venv/lib/python3.9/site-packages/sqlalchemy/pool/base.py", line 719, in checkout
    dbapi_connection = rec.get_connection()
  File "/Users/satyamtiwari/running-hub/running-hub/backend/venv/lib/python3.9/site-packages/sqlalchemy/pool/base.py", line 839, in get_connection
    self.__connect()
  File "/Users/satyamtiwari/running-hub/running-hub/backend/venv/lib/python3.9/site-packages/sqlalchemy/pool/base.py", line 903, in __connect
    pool.logger.debug("Error on connect(): %s", e)
  File "/Users/satyamtiwari/running-hub/running-hub/backend/venv/lib/python3.9/site-packages/sqlalchemy/util/langhelpers.py", line 146, in __exit__
    raise exc_value.with_traceback(exc_tb)
  File "/Users/satyamtiwari/running-hub/running-hub/backend/venv/lib/python3.9/site-packages/sqlalchemy/pool/base.py", line 898, in __connect
    self.dbapi_connection = connection = pool._invoke_creator(self)
  File "/Users/satyamtiwari/running-hub/running-hub/backend/venv/lib/python3.9/site-packages/sqlalchemy/engine/create.py", line 637, in connect
    return dialect.connect(*cargs, **cparams)
  File "/Users/satyamtiwari/running-hub/running-hub/backend/venv/lib/python3.9/site-packages/sqlalchemy/engine/default.py", line 616, in connect
    return self.loaded_dbapi.connect(*cargs, **cparams)
  File "/Users/satyamtiwari/running-hub/running-hub/backend/venv/lib/python3.9/site-packages/psycopg2/__init__.py", line 122, in connect
    conn = _connect(dsn, connection_factory=connection_factory, **kwasync)
psycopg2.OperationalError: could not translate host name "ep-small-unit-a1h4gsi7-pooler.ap-southeast-1.aws.neon.tech" to address: nodename nor servname provided, or not known


The above exception was the direct cause of the following exception:

Traceback (most recent call last):
  File "/Users/satyamtiwari/running-hub/running-hub/backend/app/api/routes.py", line 108, in get_clubs
    clubs = db.query(ClubModel).all()
  File "/Users/satyamtiwari/running-hub/running-hub/backend/venv/lib/python3.9/site-packages/sqlalchemy/orm/query.py", line 2693, in all
    return self._iter().all()  # type: ignore
  File "/Users/satyamtiwari/running-hub/running-hub/backend/venv/lib/python3.9/site-packages/sqlalchemy/orm/query.py", line 2847, in _iter
    result: Union[ScalarResult[_T], Result[_T]] = self.session.execute(
  File "/Users/satyamtiwari/running-hub/running-hub/backend/venv/lib/python3.9/site-packages/sqlalchemy/orm/session.py", line 2308, in execute
    return self._execute_internal(
  File "/Users/satyamtiwari/running-hub/running-hub/backend/venv/lib/python3.9/site-packages/sqlalchemy/orm/session.py", line 2180, in _execute_internal
    conn = self._connection_for_bind(bind)
  File "/Users/satyamtiwari/running-hub/running-hub/backend/venv/lib/python3.9/site-packages/sqlalchemy/orm/session.py", line 2047, in _connection_for_bind
    return trans._connection_for_bind(engine, execution_options)
  File "<string>", line 2, in _connection_for_bind
  File "/Users/satyamtiwari/running-hub/running-hub/backend/venv/lib/python3.9/site-packages/sqlalchemy/orm/state_changes.py", line 139, in _go
    ret_value = fn(self, *arg, **kw)
  File "/Users/satyamtiwari/running-hub/running-hub/backend/venv/lib/python3.9/site-packages/sqlalchemy/orm/session.py", line 1143, in _connection_for_bind
    conn = bind.connect()
  File "/Users/satyamtiwari/running-hub/running-hub/backend/venv/lib/python3.9/site-packages/sqlalchemy/engine/base.py", line 3268, in connect
    return self._connection_cls(self)
  File "/Users/satyamtiwari/running-hub/running-hub/backend/venv/lib/python3.9/site-packages/sqlalchemy/engine/base.py", line 147, in __init__
    Connection._handle_dbapi_exception_noconnection(
  File "/Users/satyamtiwari/running-hub/running-hub/backend/venv/lib/python3.9/site-packages/sqlalchemy/engine/base.py", line 2430, in _handle_dbapi_exception_noconnection
    raise sqlalchemy_exception.with_traceback(exc_info[2]) from e
  File "/Users/satyamtiwari/running-hub/running-hub/backend/venv/lib/python3.9/site-packages/sqlalchemy/engine/base.py", line 145, in __init__
    self._dbapi_connection = engine.raw_connection()
  File "/Users/satyamtiwari/running-hub/running-hub/backend/venv/lib/python3.9/site-packages/sqlalchemy/engine/base.py", line 3292, in raw_connection
    return self.pool.connect()
  File "/Users/satyamtiwari/running-hub/running-hub/backend/venv/lib/python3.9/site-packages/sqlalchemy/pool/base.py", line 452, in connect
    return _ConnectionFairy._checkout(self)
  File "/Users/satyamtiwari/running-hub/running-hub/backend/venv/lib/python3.9/site-packages/sqlalchemy/pool/base.py", line 1269, in _checkout
    fairy = _ConnectionRecord.checkout(pool)
  File "/Users/satyamtiwari/running-hub/running-hub/backend/venv/lib/python3.9/site-packages/sqlalchemy/pool/base.py", line 722, in checkout
    rec._checkin_failed(err, _fairy_was_created=False)
  File "/Users/satyamtiwari/running-hub/running-hub/backend/venv/lib/python3.9/site-packages/sqlalchemy/util/langhelpers.py", line 146, in __exit__
    raise exc_value.with_traceback(exc_tb)
  File "/Users/satyamtiwari/running-hub/running-hub/backend/venv/lib/python3.9/site-packages/sqlalchemy/pool/base.py", line 719, in checkout
    dbapi_connection = rec.get_connection()
  File "/Users/satyamtiwari/running-hub/running-hub/backend/venv/lib/python3.9/site-packages/sqlalchemy/pool/base.py", line 839, in get_connection
    self.__connect()
  File "/Users/satyamtiwari/running-hub/running-hub/backend/venv/lib/python3.9/site-packages/sqlalchemy/pool/base.py", line 903, in __connect
    pool.logger.debug("Error on connect(): %s", e)
  File "/Users/satyamtiwari/running-hub/running-hub/backend/venv/lib/python3.9/site-packages/sqlalchemy/util/langhelpers.py", line 146, in __exit__
    raise exc_value.with_traceback(exc_tb)
  File "/Users/satyamtiwari/running-hub/running-hub/backend/venv/lib/python3.9/site-packages/sqlalchemy/pool/base.py", line 898, in __connect
    self.dbapi_connection = connection = pool._invoke_creator(self)
  File "/Users/satyamtiwari/running-hub/running-hub/backend/venv/lib/python3.9/site-packages/sqlalchemy/engine/create.py", line 637, in connect
    return dialect.connect(*cargs, **cparams)
  File "/Users/satyamtiwari/running-hub/running-hub/backend/venv/lib/python3.9/site-packages/sqlalchemy/engine/default.py", line 616, in connect
    return self.loaded_dbapi.connect(*cargs, **cparams)
  File "/Users/satyamtiwari/running-hub/running-hub/backend/venv/lib/python3.9/site-packages/psycopg2/__init__.py", line 122, in connect
    conn = _connect(dsn, connection_factory=connection_factory, **kwasync)
sqlalchemy.exc.OperationalError: (psycopg2.OperationalError) could not translate host name "ep-small-unit-a1h4gsi7-pooler.ap-southeast-1.aws.neon.tech" to address: nodename nor servname provided, or not known

(Background on this error at: https://sqlalche.me/e/20/e3q8)
